Workbook

Sheet 配信用グラフ
Q1: 2026/6/20時点

Sheet 表
D1: 要確認
D2: 参照保留 | O2: 自動 | P2: 自動 | Q2: 自動 | R2: 自動 | S2: 自動 | T2: 自動 | U2: 自動
D3: 自動入力 | E3: 自動 | F3: 自動 | G3: 手入力 | H3: 自動 | I3: 自動 | J3: 自動 | L3: 自動 | M3: 自動 | O3: 工程
B4: 工番番号 | C4: 工事名,納期 | D4: 目標時間 | E4: 全体実数 | F4: 差 | G4: W割合 | H4: 進捗% | I4: 鍛冶目標 | J4: 鍛冶実数 | K4: 差 | L4: 溶接目標 | M4: 溶接実数 | N4: 差 | O4: 組前 | P4: 組立 | Q4: 溶接 | R4: 歪取り | S4: 塗装 | T4: 仕上げ | U4: 過去平均時間 | V4: 製作完了予想時間 | W4: 予想時間と目標時間との差
A5: 道 | B5: 251004 | C5: =INDEX(道姓班!$C$5:$C$194,MATCH(表!$B5,道姓班!$B$5:$B$194,0)) -> 養老IC 小倉高架橋P28 8/30 | D5: =INDEX(道姓班!$B$5:$B$194,MATCH(表!$B5,道姓班!$B$5:$B$194,0)+3) -> 538 | E5: =SUM(O5:T5) -> 392 | F5: =D5-E5 -> 146 | G5: 33 | H5: =INDEX(道姓班!$E$5:$E$194,MATCH(表!$B5,道姓班!$B$5:$B$194,0)+8) -> 100 | I5: =D5-L5 -> 360.46 | J5: =E5-M5 -> 273 | K5: =I5-J5 -> 87.46 | L5: =D5*G5*0.01 -> 177.54 | M5: =Q5 -> 119 | N5: =L5-M5 -> 58.54 | O5: =INDEX(道姓班!$D$5:$D$194,MATCH(表!$B5,道姓班!$B$5:$B$194,0)+1) -> 107 | P5: =INDEX(道姓班!$D$5:$D$194,MATCH(表!$B5,道姓班!$B$5:$B$194,0)+2) -> 47 | Q5: =INDEX(道姓班!$D$5:$D$194,MATCH(表!$B5,道姓班!$B$5:$B$194,0)+3) -> 119 | R5: =INDEX(道姓班!$D$5:$D$194,MATCH(表!$B5,道姓班!$B$5:$B$194,0)+4) -> 27 | S5: =INDEX(道姓班!$D$5:$D$194,MATCH(表!$B5,道姓班!$B$5:$B$194,0)+5) -> 34 | T5: =INDEX(道姓班!$D$5:$D$194,MATCH(表!$B5,道姓班!$B$5:$B$194,0)+6) -> 58 | U5: =INDEX(道姓班!$G$5:$G$194,MATCH(表!$B5,道姓班!$B$5:$B$194,0)+7) -> 456.71585 | V5: =SUM(E5/H5)*100 -> 392 | W5: =D5-V5 -> 146
B6: 24Z009 | C6: =INDEX(道姓班!$C$5:$C$194,MATCH(表!$B6,道姓班!$B$5:$B$194,0)) -> 養老IC大跡高架橋BR1P10 6/中 | D6: =INDEX(道姓班!$B$5:$B$194,MATCH(表!$B6,道姓班!$B$5:$B$194,0)+3) -> 590 | E6: =SUM(O6:T6) -> 421 | F6: =D6-E6 -> 169 | G6: 34 | H6: =INDEX(道姓班!$E$5:$E$194,MATCH(表!$B6,道姓班!$B$5:$B$194,0)+8) -> 100 | I6: =D6-L6 -> 389.4 | J6: =E6-M6 -> 298 | K6: =I6-J6 -> 91.4 | L6: =D6*G6*0.01 -> 200.6 | M6: =Q6 -> 123 | N6: =L6-M6 -> 77.6 | O6: =INDEX(道姓班!$D$5:$D$194,MATCH(表!$B6,道姓班!$B$5:$B$194,0)+1) -> 113 | P6: =INDEX(道姓班!$D$5:$D$194,MATCH(表!$B6,道姓班!$B$5:$B$194,0)+2) -> 58 | Q6: =INDEX(道姓班!$D$5:$D$194,MATCH(表!$B6,道姓班!$B$5:$B$194,0)+3) -> 123 | R6: =INDEX(道姓班!$D$5:$D$194,MATCH(表!$B6,道姓班!$B$5:$B$194,0)+4) -> 42 | S6: =INDEX(道姓班!$D$5:$D$194,MATCH(表!$B6,道姓班!$B$5:$B$194,0)+5) -> 32 | T6: =INDEX(道姓班!$D$5:$D$194,MATCH(表!$B6,道姓班!$B$5:$B$194,0)+6) -> 53 | U6: =INDEX(道姓班!$G$5:$G$194,MATCH(表!$B6,道姓班!$B$5:$B$194,0)+7) -> 480.97612 | V6: =SUM(E6/H6)*100 -> 421 | W6: =D6-V6 -> 169
B7: 251020 | C7: =INDEX(道姓班!$C$5:$C$194,MATCH(表!$B7,道姓班!$B$5:$B$194,0)) -> 畦地第二橋A1A2 27/2/15 | D7: =INDEX(道姓班!$B$5:$B$194,MATCH(表!$B7,道姓班!$B$5:$B$194,0)+3) -> 671 | E7: =SUM(O7:T7) -> 639 | F7: =D7-E7 -> 32 | G7: 33 | H7: =INDEX(道姓班!$E$5:$E$194,MATCH(表!$B7,道姓班!$B$5:$B$194,0)+8) -> 90 | I7: =D7-L7 -> 449.57 | J7: =E7-M7 -> 446 | K7: =I7-J7 -> 3.57 | L7: =D7*G7*0.01 -> 221.43 | M7: =Q7 -> 193 | N7: =L7-M7 -> 28.43 | O7: =INDEX(道姓班!$D$5:$D$194,MATCH(表!$B7,道姓班!$B$5:$B$194,0)+1) -> 252 | P7: =INDEX(道姓班!$D$5:$D$194,MATCH(表!$B7,道姓班!$B$5:$B$194,0)+2) -> 95 | Q7: =INDEX(道姓班!$D$5:$D$194,MATCH(表!$B7,道姓班!$B$5:$B$194,0)+3) -> 193 | R7: =INDEX(道姓班!$D$5:$D$194,MATCH(表!$B7,道姓班!$B$5:$B$194,0)+4) -> 60 | S7: =INDEX(道姓班!$D$5:$D$194,MATCH(表!$B7,道姓班!$B$5:$B$194,0)+5) -> 0 | T7: =INDEX(道姓班!$D$5:$D$194,MATCH(表!$B7,道姓班!$B$5:$B$194,0)+6) -> 39 | U7: =INDEX(道姓班!$G$5:$G$194,MATCH(表!$B7,道姓班!$B$5:$B$194,0)+7) -> 574.73951 | V7: =SUM(E7/H7)*100 -> 710 | W7: =D7-V7 -> -39
B8: 253009-02 | C8: =INDEX(道姓班!$C$5:$C$194,MATCH(表!$B8,道姓班!$B$5:$B$194,0)) -> 関西空港ﾉｯｸｵﾌP7桁付 10/1 | D8: =INDEX(道姓班!$B$5:$B$194,MATCH(表!$B8,道姓班!$B$5:$B$194,0)+3) -> 317 | E8: =SUM(O8:T8) -> 482 | F8: =D8-E8 -> -165 | G8: 30 | H8: =INDEX(道姓班!$E$5:$E$194,MATCH(表!$B8,道姓班!$B$5:$B$194,0)+8) -> 100 | I8: =D8-L8 -> 221.9 | J8: =E8-M8 -> 189 | K8: =I8-J8 -> 32.9 | L8: =D8*G8*0.01 -> 95.1 | M8: =Q8 -> 293 | N8: =L8-M8 -> -197.9 | O8: =INDEX(道姓班!$D$5:$D$194,MATCH(表!$B8,道姓班!$B$5:$B$194,0)+1) -> 86 | P8: =INDEX(道姓班!$D$5:$D$194,MATCH(表!$B8,道姓班!$B$5:$B$194,0)+2) -> 56 | Q8: =INDEX(道姓班!$D$5:$D$194,MATCH(表!$B8,道姓班!$B$5:$B$194,0)+3) -> 293 | R8: =INDEX(道姓班!$D$5:$D$194,MATCH(表!$B8,道姓班!$B$5:$B$194,0)+4) -> 19 | S8: =INDEX(道姓班!$D$5:$D$194,MATCH(表!$B8,道姓班!$B$5:$B$194,0)+5) -> 0 | T8: =INDEX(道姓班!$D$5:$D$194,MATCH(表!$B8,道姓班!$B$5:$B$194,0)+6) -> 28 | U8: =INDEX(道姓班!$G$5:$G$194,MATCH(表!$B8,道姓班!$B$5:$B$194,0)+7) -> 300 | V8: =SUM(E8/H8)*100 -> 482 | W8: =D8-V8 -> -165
B9: 253010-02 | C9: =INDEX(道姓班!$C$5:$C$194,MATCH(表!$B9,道姓班!$B$5:$B$194,0)) -> 関西空港ﾉｯｸｵﾌP18桁付 12/1→2/1 | D9: =INDEX(道姓班!$B$5:$B$194,MATCH(表!$B9,道姓班!$B$5:$B$194,0)+3) -> 665 | E9: =SUM(O9:T9) -> 429 | F9: =D9-E9 -> 236 | G9: 30 | H9: =INDEX(道姓班!$E$5:$E$194,MATCH(表!$B9,道姓班!$B$5:$B$194,0)+8) -> 75 | I9: =D9-L9 -> 465.5 | J9: =E9-M9 -> 184 | K9: =I9-J9 -> 281.5 | L9: =D9*G9*0.01 -> 199.5 | M9: =Q9 -> 245 | N9: =L9-M9 -> -45.5 | O9: =INDEX(道姓班!$D$5:$D$194,MATCH(表!$B9,道姓班!$B$5:$B$194,0)+1) -> 87 | P9: =INDEX(道姓班!$D$5:$D$194,MATCH(表!$B9,道姓班!$B$5:$B$194,0)+2) -> 59 | Q9: =INDEX(道姓班!$D$5:$D$194,MATCH(表!$B9,道姓班!$B$5:$B$194,0)+3) -> 245 | R9: =INDEX(道姓班!$D$5:$D$194,MATCH(表!$B9,道姓班!$B$5:$B$194,0)+4) -> 14 | S9: =INDEX(道姓班!$D$5:$D$194,MATCH(表!$B9,道姓班!$B$5:$B$194,0)+5) -> 0 | T9: =INDEX(道姓班!$D$5:$D$194,MATCH(表!$B9,道姓班!$B$5:$B$194,0)+6) -> 24 | U9: =INDEX(道姓班!$G$5:$G$194,MATCH(表!$B9,道姓班!$B$5:$B$194,0)+7) -> 0 | V9: =SUM(E9/H9)*100 -> 572 | W9: =D9-V9 -> 93
B10: 253043 | C10: =INDEX(道姓班!$C$5:$C$194,MATCH(表!$B10,道姓班!$B$5:$B$194,0)) -> 関西空港ﾉｯｸｵﾌP14脚付 塗前6/中 | D10: =INDEX(道姓班!$B$5:$B$194,MATCH(表!$B10,道姓班!$B$5:$B$194,0)+3) -> 367 | E10: =SUM(O10:T10) -> 529 | F10: =D10-E10 -> -162 | G10: 30 | H10: =INDEX(道姓班!$E$5:$E$194,MATCH(表!$B10,道姓班!$B$5:$B$194,0)+8) -> 75 | I10: =D10-L10 -> 256.9 | J10: =E10-M10 -> 290 | K10: =I10-J10 -> -33.1 | L10: =D10*G10*0.01 -> 110.1 | M10: =Q10 -> 239 | N10: =L10-M10 -> -128.9 | O10: =INDEX(道姓班!$D$5:$D$194,MATCH(表!$B10,道姓班!$B$5:$B$194,0)+1) -> 190 | P10: =INDEX(道姓班!$D$5:$D$194,MATCH(表!$B10,道姓班!$B$5:$B$194,0)+2) -> 63 | Q10: =INDEX(道姓班!$D$5:$D$194,MATCH(表!$B10,道姓班!$B$5:$B$194,0)+3) -> 239 | R10: =INDEX(道姓班!$D$5:$D$194,MATCH(表!$B10,道姓班!$B$5:$B$194,0)+4) -> 6 | S10: =INDEX(道姓班!$D$5:$D$194,MATCH(表!$B10,道姓班!$B$5:$B$194,0)+5) -> 0 | T10: =INDEX(道姓班!$D$5:$D$194,MATCH(表!$B10,道姓班!$B$5:$B$194,0)+6) -> 31 | U10: =INDEX(道姓班!$G$5:$G$194,MATCH(表!$B10,道姓班!$B$5:$B$194,0)+7) -> 0 | V10: =SUM(E10/H10)*100 -> 705.33333 | W10: =D10-V10 -> -338.33333
B11: 253011 | C11: =INDEX(道姓班!$C$5:$C$194,MATCH(表!$B11,道姓班!$B$5:$B$194,0)) -> 関西空港ﾉｯｸｵﾌP14桁付 12/1 | D11: =INDEX(道姓班!$B$5:$B$194,MATCH(表!$B11,道姓班!$B$5:$B$194,0)+3) -> 1095 | E11: =SUM(O11:T11) -> 290 | F11: =D11-E11 -> 805 | G11: 30 | H11: =INDEX(道姓班!$E$5:$E$194,MATCH(表!$B11,道姓班!$B$5:$B$194,0)+8) -> 40 | I11: =D11-L11 -> 766.5 | J11: =E11-M11 -> 172 | K11: =I11-J11 -> 594.5 | L11: =D11*G11*0.01 -> 328.5 | M11: =Q11 -> 118 | N11: =L11-M11 -> 210.5 | O11: =INDEX(道姓班!$D$5:$D$194,MATCH(表!$B11,道姓班!$B$5:$B$194,0)+1) -> 157 | P11: =INDEX(道姓班!$D$5:$D$194,MATCH(表!$B11,道姓班!$B$5:$B$194,0)+2) -> 15 | Q11: =INDEX(道姓班!$D$5:$D$194,MATCH(表!$B11,道姓班!$B$5:$B$194,0)+3) -> 118 | R11: =INDEX(道姓班!$D$5:$D$194,MATCH(表!$B11,道姓班!$B$5:$B$194,0)+4) -> 0 | S11: =INDEX(道姓班!$D$5:$D$194,MATCH(表!$B11,道姓班!$B$5:$B$194,0)+5) -> 0 | T11: =INDEX(道姓班!$D$5:$D$194,MATCH(表!$B11,道姓班!$B$5:$B$194,0)+6) -> 0 | U11: =INDEX(道姓班!$G$5:$G$194,MATCH(表!$B11,道姓班!$B$5:$B$194,0)+7) -> 0 | V11: =SUM(E11/H11)*100 -> 725 | W11: =D11-V11 -> 370
B12: 247023-03 | C12: =INDEX(道姓班!$C$5:$C$194,MATCH(表!$B12,道姓班!$B$5:$B$194,0)) -> 養老IC本線他3橋 小倉P44,A2 5/末6月 | D12: =INDEX(道姓班!$B$5:$B$194,MATCH(表!$B12,道姓班!$B$5:$B$194,0)+3) -> 861 | E12: =SUM(O12:T12) -> 851 | F12: =D12-E12 -> 10 | G12: 34 | H12: =INDEX(道姓班!$E$5:$E$194,MATCH(表!$B12,道姓班!$B$5:$B$194,0)+8) -> 100 | I12: =D12-L12 -> 568.26 | J12: =E12-M12 -> 540 | K12: =I12-J12 -> 28.26 | L12: =D12*G12*0.01 -> 292.74 | M12: =Q12 -> 311 | N12: =L12-M12 -> -18.26 | O12: =INDEX(道姓班!$D$5:$D$194,MATCH(表!$B12,道姓班!$B$5:$B$194,0)+1) -> 175 | P12: =INDEX(道姓班!$D$5:$D$194,MATCH(表!$B12,道姓班!$B$5:$B$194,0)+2) -> 105 | Q12: =INDEX(道姓班!$D$5:$D$194,MATCH(表!$B12,道姓班!$B$5:$B$194,0)+3) -> 311 | R12: =INDEX(道姓班!$D$5:$D$194,MATCH(表!$B12,道姓班!$B$5:$B$194,0)+4) -> 52 | S12: =INDEX(道姓班!$D$5:$D$194,MATCH(表!$B12,道姓班!$B$5:$B$194,0)+5) -> 84 | T12: =INDEX(道姓班!$D$5:$D$194,MATCH(表!$B12,道姓班!$B$5:$B$194,0)+6) -> 124 | U12: =INDEX(道姓班!$G$5:$G$194,MATCH(表!$B12,道姓班!$B$5:$B$194,0)+7) -> 850.79378 | V12: =SUM(E12/H12)*100 -> 851 | W12: =D12-V12 -> 10
B13: 253018 | C13: =INDEX(道姓班!$C$5:$C$194,MATCH(表!$B13,道姓班!$B$5:$B$194,0)) -> 養老 大跡高架橋BR3(P22) R8/9/中 | D13: =INDEX(道姓班!$B$5:$B$194,MATCH(表!$B13,道姓班!$B$5:$B$194,0)+3) -> 598 | E13: =SUM(O13:T13) -> 540 | F13: =D13-E13 -> 58 | G13: 33 | H13: =INDEX(道姓班!$E$5:$E$194,MATCH(表!$B13,道姓班!$B$5:$B$194,0)+8) -> 85 | I13: =D13-L13 -> 400.66 | J13: =E13-M13 -> 301 | K13: =I13-J13 -> 99.66 | L13: =D13*G13*0.01 -> 197.34 | M13: =Q13 -> 239 | N13: =L13-M13 -> -41.66 | O13: =INDEX(道姓班!$D$5:$D$194,MATCH(表!$B13,道姓班!$B$5:$B$194,0)+1) -> 165 | P13: =INDEX(道姓班!$D$5:$D$194,MATCH(表!$B13,道姓班!$B$5:$B$194,0)+2) -> 50 | Q13: =INDEX(道姓班!$D$5:$D$194,MATCH(表!$B13,道姓班!$B$5:$B$194,0)+3) -> 239 | R13: =INDEX(道姓班!$D$5:$D$194,MATCH(表!$B13,道姓班!$B$5:$B$194,0)+4) -> 37 | S13: =INDEX(道姓班!$D$5:$D$194,MATCH(表!$B13,道姓班!$B$5:$B$194,0)+5) -> 0 | T13: =INDEX(道姓班!$D$5:$D$194,MATCH(表!$B13,道姓班!$B$5:$B$194,0)+6) -> 49 | U13: =INDEX(道姓班!$G$5:$G$194,MATCH(表!$B13,道姓班!$B$5:$B$194,0)+7) -> 487.28271 | V13: =SUM(E13/H13)*100 -> 635.29412 | W13: =D13-V13 -> -37.294118
B14: 247023-01 | C14: =INDEX(道姓班!$C$5:$C$194,MATCH(表!$B14,道姓班!$B$5:$B$194,0)) -> 養老IC本線他3橋 小倉P38 5/30 | D14: =INDEX(道姓班!$B$5:$B$194,MATCH(表!$B14,道姓班!$B$5:$B$194,0)+3) -> 660 | E14: =SUM(O14:T14) -> 503 | F14: =D14-E14 -> 157 | G14: 33 | H14: =INDEX(道姓班!$E$5:$E$194,MATCH(表!$B14,道姓班!$B$5:$B$194,0)+8) -> 100 | I14: =D14-L14 -> 442.2 | J14: =E14-M14 -> 345 | K14: =I14-J14 -> 97.2 | L14: =D14*G14*0.01 -> 217.8 | M14: =Q14 -> 158 | N14: =L14-M14 -> 59.8 | O14: =INDEX(道姓班!$D$5:$D$194,MATCH(表!$B14,道姓班!$B$5:$B$194,0)+1) -> 164 | P14: =INDEX(道姓班!$D$5:$D$194,MATCH(表!$B14,道姓班!$B$5:$B$194,0)+2) -> 66 | Q14: =INDEX(道姓班!$D$5:$D$194,MATCH(表!$B14,道姓班!$B$5:$B$194,0)+3) -> 158 | R14: =INDEX(道姓班!$D$5:$D$194,MATCH(表!$B14,道姓班!$B$5:$B$194,0)+4) -> 14 | S14: =INDEX(道姓班!$D$5:$D$194,MATCH(表!$B14,道姓班!$B$5:$B$194,0)+5) -> 35 | T14: =INDEX(道姓班!$D$5:$D$194,MATCH(表!$B14,道姓班!$B$5:$B$194,0)+6) -> 66 | U14: =INDEX(道姓班!$G$5:$G$194,MATCH(表!$B14,道姓班!$B$5:$B$194,0)+7) -> 430.09639 | V14: =SUM(E14/H14)*100 -> 503 | W14: =D14-V14 -> 157
A15: 阪 | B15: =阪上班!$B$126 -> 23Z035 | C15: =INDEX(阪上班!$C$5:$C$233,MATCH(表!$B15,阪上班!$B$5:$B$233,0)) -> 門真高架橋P60 26/12/25 | D15: =INDEX(阪上班!$B$5:$B$233,MATCH(表!$B15,阪上班!$B$5:$B$233,0)+3) -> 940 | E15: =SUM(O15:T15) -> 665 | F15: =D15-E15 -> 275 | G15: 33.4 | H15: =INDEX(阪上班!$E$5:$E$233,MATCH(表!$B15,阪上班!$B$5:$B$233,0)+8) -> 100 | I15: =D15-L15 -> 626.04 | J15: =E15-M15 -> 438 | K15: =I15-J15 -> 188.04 | L15: =D15*G15*0.01 -> 313.96 | M15: =Q15 -> 227 | N15: =L15-M15 -> 86.96 | O15: =INDEX(阪上班!$D$5:$D$233,MATCH(表!$B15,阪上班!$B$5:$B$233,0)+1) -> 182 | P15: =INDEX(阪上班!$D$5:$D$233,MATCH(表!$B15,阪上班!$B$5:$B$233,0)+2) -> 50 | Q15: =INDEX(阪上班!$D$5:$D$233,MATCH(表!$B15,阪上班!$B$5:$B$233,0)+3) -> 227 | R15: =INDEX(阪上班!$D$5:$D$233,MATCH(表!$B15,阪上班!$B$5:$B$233,0)+4) -> 45 | S15: =INDEX(阪上班!$D$5:$D$233,MATCH(表!$B15,阪上班!$B$5:$B$233,0)+5) -> 104 | T15: =INDEX(阪上班!$D$5:$D$233,MATCH(表!$B15,阪上班!$B$5:$B$233,0)+6) -> 57 | U15: =INDEX(阪上班!$G$5:$G$233,MATCH(表!$B15,阪上班!$B$5:$B$233,0)+7) -> 677.06976 | V15: =SUM(E15/H15)*100 -> 665 | W15: =D15-V15 -> 275
B16: 248015 | C16: =INDEX(阪上班!$C$5:$C$233,MATCH(表!$B16,阪上班!$B$5:$B$233,0)) -> 北真志野 上りA1A2 9/10 | D16: =INDEX(阪上班!$B$5:$B$233,MATCH(表!$B16,阪上班!$B$5:$B$233,0)+3) -> 500 | E16: =SUM(O16:T16) -> 88 | F16: =D16-E16 -> 412 | G16: 33 | H16: =INDEX(阪上班!$E$5:$E$233,MATCH(表!$B16,阪上班!$B$5:$B$233,0)+8) -> 10 | I16: =D16-L16 -> 335 | J16: =E16-M16 -> 88 | K16: =I16-J16 -> 247 | L16: =D16*G16*0.01 -> 165 | M16: =Q16 -> 0 | N16: =L16-M16 -> 165 | O16: =INDEX(阪上班!$D$5:$D$233,MATCH(表!$B16,阪上班!$B$5:$B$233,0)+1) -> 57 | P16: =INDEX(阪上班!$D$5:$D$233,MATCH(表!$B16,阪上班!$B$5:$B$233,0)+2) -> 0 | Q16: =INDEX(阪上班!$D$5:$D$233,MATCH(表!$B16,阪上班!$B$5:$B$233,0)+3) -> 0 | R16: =INDEX(阪上班!$D$5:$D$233,MATCH(表!$B16,阪上班!$B$5:$B$233,0)+4) -> 0 | S16: =INDEX(阪上班!$D$5:$D$233,MATCH(表!$B16,阪上班!$B$5:$B$233,0)+5) -> 0 | T16: =INDEX(阪上班!$D$5:$D$233,MATCH(表!$B16,阪上班!$B$5:$B$233,0)+6) -> 31 | U16: =INDEX(阪上班!$G$5:$G$233,MATCH(表!$B16,阪上班!$B$5:$B$233,0)+7) -> 502.80711 | V16: =SUM(E16/H16)*100 -> 880 | W16: =D16-V16 -> -380
B17: 25Y025 | C17: =INDEX(阪上班!$C$5:$C$233,MATCH(表!$B17,阪上班!$B$5:$B$233,0)) -> 温品下部工ブラケット7/15メッキ入 | D17: =INDEX(阪上班!$B$5:$B$233,MATCH(表!$B17,阪上班!$B$5:$B$233,0)+3) -> 65 | E17: =SUM(O17:T17) -> 141 | F17: =D17-E17 -> -76 | G17: 35.4 | H17: =INDEX(阪上班!$E$5:$E$233,MATCH(表!$B17,阪上班!$B$5:$B$233,0)+8) -> 0 | I17: =D17-L17 -> 41.99 | J17: =E17-M17 -> 82 | K17: =I17-J17 -> -40.01 | L17: =D17*G17*0.01 -> 23.01 | M17: =Q17 -> 59 | N17: =L17-M17 -> -35.99 | O17: =INDEX(阪上班!$D$5:$D$233,MATCH(表!$B17,阪上班!$B$5:$B$233,0)+1) -> 53 | P17: =INDEX(阪上班!$D$5:$D$233,MATCH(表!$B17,阪上班!$B$5:$B$233,0)+2) -> 21 | Q17: =INDEX(阪上班!$D$5:$D$233,MATCH(表!$B17,阪上班!$B$5:$B$233,0)+3) -> 59 | R17: =INDEX(阪上班!$D$5:$D$233,MATCH(表!$B17,阪上班!$B$5:$B$233,0)+4) -> 8 | S17: =INDEX(阪上班!$D$5:$D$233,MATCH(表!$B17,阪上班!$B$5:$B$233,0)+5) -> 0 | T17: =INDEX(阪上班!$D$5:$D$233,MATCH(表!$B17,阪上班!$B$5:$B$233,0)+6) -> 0 | U17: =INDEX(阪上班!$G$5:$G$233,MATCH(表!$B17,阪上班!$B$5:$B$233,0)+7) -> 0 | V17: =SUM(E17/H17)*100 -> #DIV/0! | W17: =D17-V17 -> #DIV/0!
B18: 264010 | C18: =INDEX(阪上班!$C$5:$C$233,MATCH(表!$B18,阪上班!$B$5:$B$233,0)) -> 八潮PAﾗﾝﾌﾟ橋PC3橋脚 7/15 | D18: =INDEX(阪上班!$B$5:$B$233,MATCH(表!$B18,阪上班!$B$5:$B$233,0)+3) -> 438 | E18: =SUM(O18:T18) -> 304 | F18: =D18-E18 -> 134 | G18: 30 | H18: =INDEX(阪上班!$E$5:$E$233,MATCH(表!$B18,阪上班!$B$5:$B$233,0)+8) -> 40 | I18: =D18-L18 -> 306.6 | J18: =E18-M18 -> 73 | K18: =I18-J18 -> 233.6 | L18: =D18*G18*0.01 -> 131.4 | M18: =Q18 -> 231 | N18: =L18-M18 -> -99.6 | O18: =INDEX(阪上班!$D$5:$D$233,MATCH(表!$B18,阪上班!$B$5:$B$233,0)+1) -> 26 | P18: =INDEX(阪上班!$D$5:$D$233,MATCH(表!$B18,阪上班!$B$5:$B$233,0)+2) -> 30 | Q18: =INDEX(阪上班!$D$5:$D$233,MATCH(表!$B18,阪上班!$B$5:$B$233,0)+3) -> 231 | R18: =INDEX(阪上班!$D$5:$D$233,MATCH(表!$B18,阪上班!$B$5:$B$233,0)+4) -> 17 | S18: =INDEX(阪上班!$D$5:$D$233,MATCH(表!$B18,阪上班!$B$5:$B$233,0)+5) -> 0 | T18: =INDEX(阪上班!$D$5:$D$233,MATCH(表!$B18,阪上班!$B$5:$B$233,0)+6) -> 0 | U18: =INDEX(阪上班!$G$5:$G$233,MATCH(表!$B18,阪上班!$B$5:$B$233,0)+7) -> 0 | V18: =SUM(E18/H18)*100 -> 760 | W18: =D18-V18 -> -322
B19: 251019 | C19: =INDEX(阪上班!$C$5:$C$233,MATCH(表!$B19,阪上班!$B$5:$B$233,0)) -> 畦地第一橋A1A2 12/15 | D19: =INDEX(阪上班!$B$5:$B$233,MATCH(表!$B19,阪上班!$B$5:$B$233,0)+3) -> 614 | E19: =SUM(O19:T19) -> 519 | F19: =D19-E19 -> 95 | G19: 33 | H19: =INDEX(阪上班!$E$5:$E$233,MATCH(表!$B19,阪上班!$B$5:$B$233,0)+8) -> 90 | I19: =D19-L19 -> 411.38 | J19: =E19-M19 -> 338 | K19: =I19-J19 -> 73.38 | L19: =D19*G19*0.01 -> 202.62 | M19: =Q19 -> 181 | N19: =L19-M19 -> 21.62 | O19: =INDEX(阪上班!$D$5:$D$233,MATCH(表!$B19,阪上班!$B$5:$B$233,0)+1) -> 162 | P19: =INDEX(阪上班!$D$5:$D$233,MATCH(表!$B19,阪上班!$B$5:$B$233,0)+2) -> 54 | Q19: =INDEX(阪上班!$D$5:$D$233,MATCH(表!$B19,阪上班!$B$5:$B$233,0)+3) -> 181 | R19: =INDEX(阪上班!$D$5:$D$233,MATCH(表!$B19,阪上班!$B$5:$B$233,0)+4) -> 34 | S19: =INDEX(阪上班!$D$5:$D$233,MATCH(表!$B19,阪上班!$B$5:$B$233,0)+5) -> 0 | T19: =INDEX(阪上班!$D$5:$D$233,MATCH(表!$B19,阪上班!$B$5:$B$233,0)+6) -> 88 | U19: =INDEX(阪上班!$G$5:$G$233,MATCH(表!$B19,阪上班!$B$5:$B$233,0)+7) -> 567.69287 | V19: =SUM(E19/H19)*100 -> 576.66667 | W19: =D19-V19 -> 37.333333
B20: 248020 | C20: =INDEX(阪上班!$C$5:$C$233,MATCH(表!$B20,阪上班!$B$5:$B$233,0)) -> 養老 小倉BR2(P34) 現地7/初 | D20: =INDEX(阪上班!$B$5:$B$233,MATCH(表!$B20,阪上班!$B$5:$B$233,0)+3) -> 479 | E20: =SUM(O20:T20) -> 413 | F20: =D20-E20 -> 66 | G20: 33 | H20: =INDEX(阪上班!$E$5:$E$233,MATCH(表!$B20,阪上班!$B$5:$B$233,0)+8) -> 100 | I20: =D20-L20 -> 320.93 | J20: =E20-M20 -> 272 | K20: =I20-J20 -> 48.93 | L20: =D20*G20*0.01 -> 158.07 | M20: =Q20 -> 141 | N20: =L20-M20 -> 17.07 | O20: =INDEX(阪上班!$D$5:$D$233,MATCH(表!$B20,阪上班!$B$5:$B$233,0)+1) -> 98 | P20: =INDEX(阪上班!$D$5:$D$233,MATCH(表!$B20,阪上班!$B$5:$B$233,0)+2) -> 34 | Q20: =INDEX(阪上班!$D$5:$D$233,MATCH(表!$B20,阪上班!$B$5:$B$233,0)+3) -> 141 | R20: =INDEX(阪上班!$D$5:$D$233,MATCH(表!$B20,阪上班!$B$5:$B$233,0)+4) -> 37 | S20: =INDEX(阪上班!$D$5:$D$233,MATCH(表!$B20,阪上班!$B$5:$B$233,0)+5) -> 58 | T20: =INDEX(阪上班!$D$5:$D$233,MATCH(表!$B20,阪上班!$B$5:$B$233,0)+6) -> 45 | U20: =INDEX(阪上班!$G$5:$G$233,MATCH(表!$B20,阪上班!$B$5:$B$233,0)+7) -> 383.12617 | V20: =SUM(E20/H20)*100 -> 413 | W20: =D20-V20 -> 66
B21: 247023-02 | C21: =INDEX(阪上班!$C$5:$C$233,MATCH(表!$B21,阪上班!$B$5:$B$233,0)) -> 養老IC本線他3橋 本線P5,A1 8月下旬頃 | D21: =INDEX(阪上班!$B$5:$B$233,MATCH(表!$B21,阪上班!$B$5:$B$233,0)+3) -> 1952 | E21: =SUM(O21:T21) -> 1244 | F21: =D21-E21 -> 708 | G21: 33 | H21: =INDEX(阪上班!$E$5:$E$233,MATCH(表!$B21,阪上班!$B$5:$B$233,0)+8) -> 70 | I21: =D21-L21 -> 1307.84 | J21: =E21-M21 -> 765 | K21: =I21-J21 -> 542.84 | L21: =D21*G21*0.01 -> 644.16 | M21: =Q21 -> 479 | N21: =L21-M21 -> 165.16 | O21: =INDEX(阪上班!$D$5:$D$233,MATCH(表!$B21,阪上班!$B$5:$B$233,0)+1) -> 374 | P21: =INDEX(阪上班!$D$5:$D$233,MATCH(表!$B21,阪上班!$B$5:$B$233,0)+2) -> 152 | Q21: =INDEX(阪上班!$D$5:$D$233,MATCH(表!$B21,阪上班!$B$5:$B$233,0)+3) -> 479 | R21: =INDEX(阪上班!$D$5:$D$233,MATCH(表!$B21,阪上班!$B$5:$B$233,0)+4) -> 102 | S21: =INDEX(阪上班!$D$5:$D$233,MATCH(表!$B21,阪上班!$B$5:$B$233,0)+5) -> 39 | T21: =INDEX(阪上班!$D$5:$D$233,MATCH(表!$B21,阪上班!$B$5:$B$233,0)+6) -> 98 | U21: =INDEX(阪上班!$G$5:$G$233,MATCH(表!$B21,阪上班!$B$5:$B$233,0)+7) -> 1540.2558 | V21: =SUM(E21/H21)*100 -> 1777.1429 | W21: =D21-V21 -> 174.85714
B22: =阪上班!$B$136 -> 22Y005 | C22: =INDEX(阪上班!$C$5:$C$233,MATCH(表!$B22,阪上班!$B$5:$B$233,0)) -> 富野高架橋中 A2 3/24現予 | D22: =INDEX(阪上班!$B$5:$B$233,MATCH(表!$B22,阪上班!$B$5:$B$233,0)+3) -> 1448 | E22: =SUM(O22:T22) -> 1086 | F22: =D22-E22 -> 362 | G22: 33.4 | H22: =INDEX(阪上班!$E$5:$E$233,MATCH(表!$B22,阪上班!$B$5:$B$233,0)+8) -> 100 | I22: =D22-L22 -> 964.368 | J22: =E22-M22 -> 658 | K22: =I22-J22 -> 306.368 | L22: =D22*G22*0.01 -> 483.632 | M22: =Q22 -> 428 | N22: =L22-M22 -> 55.632 | O22: =INDEX(阪上班!$D$5:$D$233,MATCH(表!$B22,阪上班!$B$5:$B$233,0)+1) -> 351 | P22: =INDEX(阪上班!$D$5:$D$233,MATCH(表!$B22,阪上班!$B$5:$B$233,0)+2) -> 92 | Q22: =INDEX(阪上班!$D$5:$D$233,MATCH(表!$B22,阪上班!$B$5:$B$233,0)+3) -> 428 | R22: =INDEX(阪上班!$D$5:$D$233,MATCH(表!$B22,阪上班!$B$5:$B$233,0)+4) -> 78 | S22: =INDEX(阪上班!$D$5:$D$233,MATCH(表!$B22,阪上班!$B$5:$B$233,0)+5) -> 7 | T22: =INDEX(阪上班!$D$5:$D$233,MATCH(表!$B22,阪上班!$B$5:$B$233,0)+6) -> 130 | U22: =INDEX(阪上班!$G$5:$G$233,MATCH(表!$B22,阪上班!$B$5:$B$233,0)+7) -> 1269.5147 | V22: =SUM(E22/H22)*100 -> 1086 | W22: =D22-V22 -> 362
A23: 中 | B23: 257021 | C23: =INDEX(中野班!$C$5:$C$142,MATCH(表!$B23,中野班!$B$5:$B$142,0)) -> 丁野橋上りA1A2 9/14 9/25 | D23: =INDEX(中野班!$B$5:$B$142,MATCH(表!$B23,中野班!$B$5:$B$142,0)+3) -> 718 | E23: =SUM(O23:T23) -> 524 | F23: =D23-E23 -> 194 | G23: 33 | H23: =INDEX(中野班!$E$5:$E$142,MATCH(表!$B23,中野班!$B$5:$B$142,0)+8) -> 55 | I23: =D23-L23 -> 481.06 | J23: =E23-M23 -> 288 | K23: =I23-J23 -> 193.06 | L23: =D23*G23*0.01 -> 236.94 | M23: =Q23 -> 236 | N23: =L23-M23 -> 0.94 | O23: =INDEX(中野班!$D$5:$D$142,MATCH(表!$B23,中野班!$B$5:$B$142,0)+1) -> 193 | P23: =INDEX(中野班!$D$5:$D$142,MATCH(表!$B23,中野班!$B$5:$B$142,0)+2) -> 72 | Q23: =INDEX(中野班!$D$5:$D$142,MATCH(表!$B23,中野班!$B$5:$B$142,0)+3) -> 236 | R23: =INDEX(中野班!$D$5:$D$142,MATCH(表!$B23,中野班!$B$5:$B$142,0)+4) -> 20 | S23: =INDEX(中野班!$D$5:$D$142,MATCH(表!$B23,中野班!$B$5:$B$142,0)+5) -> 0 | T23: =INDEX(中野班!$D$5:$D$142,MATCH(表!$B23,中野班!$B$5:$B$142,0)+6) -> 3 | U23: =INDEX(中野班!$G$5:$G$142,MATCH(表!$B23,中野班!$B$5:$B$142,0)+7) -> 672.63519 | V23: =SUM(E23/H23)*100 -> 952.72727 | W23: =D23-V23 -> -234.72727
B24: 263018-01 | C24: =INDEX(中野班!$C$5:$C$142,MATCH(表!$B24,中野班!$B$5:$B$142,0)) -> 大鳴門自転車道 鋼床版台座 9/15 | D24: =INDEX(中野班!$B$5:$B$142,MATCH(表!$B24,中野班!$B$5:$B$142,0)+3) -> 3268 | E24: =SUM(O24:T24) -> 964 | F24: =D24-E24 -> 2304 | G24: 25 | H24: =INDEX(中野班!$E$5:$E$142,MATCH(表!$B24,中野班!$B$5:$B$142,0)+8) -> 12.4 | I24: =D24-L24 -> 2451 | J24: =E24-M24 -> 659 | K24: =I24-J24 -> 1792 | L24: =D24*G24*0.01 -> 817 | M24: =Q24 -> 305 | N24: =L24-M24 -> 512 | O24: =INDEX(中野班!$D$5:$D$142,MATCH(表!$B24,中野班!$B$5:$B$142,0)+1) -> 496 | P24: =INDEX(中野班!$D$5:$D$142,MATCH(表!$B24,中野班!$B$5:$B$142,0)+2) -> 155 | Q24: =INDEX(中野班!$D$5:$D$142,MATCH(表!$B24,中野班!$B$5:$B$142,0)+3) -> 305 | R24: =INDEX(中野班!$D$5:$D$142,MATCH(表!$B24,中野班!$B$5:$B$142,0)+4) -> 8 | S24: =INDEX(中野班!$D$5:$D$142,MATCH(表!$B24,中野班!$B$5:$B$142,0)+5) -> 0 | T24: =INDEX(中野班!$D$5:$D$142,MATCH(表!$B24,中野班!$B$5:$B$142,0)+6) -> 0 | U24: =INDEX(中野班!$G$5:$G$142,MATCH(表!$B24,中野班!$B$5:$B$142,0)+7) -> 0 | V24: =SUM(E24/H24)*100 -> 7774.1935 | W24: =D24-V24 -> -4506.1935
B25: 265007 | C25: =INDEX(中野班!$C$5:$C$142,MATCH(表!$B25,中野班!$B$5:$B$142,0)) -> 浦郷 配管支持金具 7/10 | D25: =INDEX(中野班!$B$5:$B$142,MATCH(表!$B25,中野班!$B$5:$B$142,0)+3) -> 246 | E25: =SUM(O25:T25) -> 223 | F25: =D25-E25 -> 23 | G25: 25 | H25: =INDEX(中野班!$E$5:$E$142,MATCH(表!$B25,中野班!$B$5:$B$142,0)+8) -> 60 | I25: =D25-L25 -> 184.5 | J25: =E25-M25 -> 198 | K25: =I25-J25 -> -13.5 | L25: =D25*G25*0.01 -> 61.5 | M25: =Q25 -> 25 | N25: =L25-M25 -> 36.5 | O25: =INDEX(中野班!$D$5:$D$142,MATCH(表!$B25,中野班!$B$5:$B$142,0)+1) -> 168 | P25: =INDEX(中野班!$D$5:$D$142,MATCH(表!$B25,中野班!$B$5:$B$142,0)+2) -> 30 | Q25: =INDEX(中野班!$D$5:$D$142,MATCH(表!$B25,中野班!$B$5:$B$142,0)+3) -> 25 | R25: =INDEX(中野班!$D$5:$D$142,MATCH(表!$B25,中野班!$B$5:$B$142,0)+4) -> 0 | S25: =INDEX(中野班!$D$5:$D$142,MATCH(表!$B25,中野班!$B$5:$B$142,0)+5) -> 0 | T25: =INDEX(中野班!$D$5:$D$142,MATCH(表!$B25,中野班!$B$5:$B$142,0)+6) -> 0 | U25: =INDEX(中野班!$G$5:$G$142,MATCH(表!$B25,中野班!$B$5:$B$142,0)+7) -> 0 | V25: =SUM(E25/H25)*100 -> 371.66667 | W25: =D25-V25 -> -125.66667
B26: 246017 | C26: =INDEX(中野班!$C$5:$C$142,MATCH(表!$B26,中野班!$B$5:$B$142,0)) -> 国道7号西山崎地区 9/14 | D26: =INDEX(中野班!$B$5:$B$142,MATCH(表!$B26,中野班!$B$5:$B$142,0)+3) -> 843 | E26: =SUM(O26:T26) -> 197 | F26: =D26-E26 -> 646 | G26: 29.4 | H26: =INDEX(中野班!$E$5:$E$142,MATCH(表!$B26,中野班!$B$5:$B$142,0)+8) -> 25 | I26: =D26-L26 -> 595.158 | J26: =E26-M26 -> 183 | K26: =I26-J26 -> 412.158 | L26: =D26*G26*0.01 -> 247.842 | M26: =Q26 -> 14 | N26: =L26-M26 -> 233.842 | O26: =INDEX(中野班!$D$5:$D$142,MATCH(表!$B26,中野班!$B$5:$B$142,0)+1) -> 136 | P26: =INDEX(中野班!$D$5:$D$142,MATCH(表!$B26,中野班!$B$5:$B$142,0)+2) -> 47 | Q26: =INDEX(中野班!$D$5:$D$142,MATCH(表!$B26,中野班!$B$5:$B$142,0)+3) -> 14 | R26: =INDEX(中野班!$D$5:$D$142,MATCH(表!$B26,中野班!$B$5:$B$142,0)+4) -> 0 | S26: =INDEX(中野班!$D$5:$D$142,MATCH(表!$B26,中野班!$B$5:$B$142,0)+5) -> 0 | T26: =INDEX(中野班!$D$5:$D$142,MATCH(表!$B26,中野班!$B$5:$B$142,0)+6) -> 0 | U26: =INDEX(中野班!$G$5:$G$142,MATCH(表!$B26,中野班!$B$5:$B$142,0)+7) -> 632.67271 | V26: =SUM(E26/H26)*100 -> 788 | W26: =D26-V26 -> 55
B27: 261022 | C27: =INDEX(中野班!$C$5:$C$142,MATCH(表!$B27,中野班!$B$5:$B$142,0)) -> 中之口川床版取替 6/15 9/15 | D27: =INDEX(中野班!$B$5:$B$142,MATCH(表!$B27,中野班!$B$5:$B$142,0)+3) -> 1325 | E27: =SUM(O27:T27) -> 754 | F27: =D27-E27 -> 571 | G27: 20 | H27: =INDEX(中野班!$E$5:$E$142,MATCH(表!$B27,中野班!$B$5:$B$142,0)+8) -> 36.1 | I27: =D27-L27 -> 1060 | J27: =E27-M27 -> 507 | K27: =I27-J27 -> 553 | L27: =D27*G27*0.01 -> 265 | M27: =Q27 -> 247 | N27: =L27-M27 -> 18 | O27: =INDEX(中野班!$D$5:$D$142,MATCH(表!$B27,中野班!$B$5:$B$142,0)+1) -> 184 | P27: =INDEX(中野班!$D$5:$D$142,MATCH(表!$B27,中野班!$B$5:$B$142,0)+2) -> 60 | Q27: =INDEX(中野班!$D$5:$D$142,MATCH(表!$B27,中野班!$B$5:$B$142,0)+3) -> 247 | R27: =INDEX(中野班!$D$5:$D$142,MATCH(表!$B27,中野班!$B$5:$B$142,0)+4) -> 37 | S27: =INDEX(中野班!$D$5:$D$142,MATCH(表!$B27,中野班!$B$5:$B$142,0)+5) -> 65 | T27: =INDEX(中野班!$D$5:$D$142,MATCH(表!$B27,中野班!$B$5:$B$142,0)+6) -> 161 | U27: =INDEX(中野班!$G$5:$G$142,MATCH(表!$B27,中野班!$B$5:$B$142,0)+7) -> 1781.6311 | V27: =SUM(E27/H27)*100 -> 2088.6427 | W27: =D27-V27 -> -763.64266

Sheet モデル
P5: 30
AX6: 31
R8: =SUM(R2:R7) -> 0 | S8: =SUM(S2:S7) -> 0 | T8: =SUM(T2:T7) -> 0 | U8: =SUM(U2:U7) -> 0 | V8: =SUM(V2:V7) -> 0 | W8: =SUM(W2:W7) -> 0 | X8: =SUM(X2:X7) -> 0 | Y8: =SUM(Y2:Y7) -> 0 | ... AU8: =SUM(AU2:AU7) -> 0 | AZ8: =SUM(AZ2:AZ7) -> 0 | BA8: =SUM(BA2:BA7) -> 0 | BB8: =SUM(BB2:BB7) -> 0 | BC8: =SUM(BC2:BC7) -> 0 | BD8: =SUM(BD2:BD7) -> 0 | BE8: =SUM(BE2:BE7) -> 0 | BF8: =SUM(BF2:BF7) -> 0 | BG8: =SUM(BG2:BG7) -> 0 | ... CD8: =SUM(CD2:CD7) -> 0
R9: 組前 | T9: =SUM(R2:AU2) -> 0 | V9: 組立 | X9: =SUM(R3:AU3) -> 0 | Z9: 溶接 | AB9: =SUM(R4:AU4) -> 0 | AD9: 歪取 | AF9: =SUM(R5:AU5) -> 0 | AH9: 塗装 | AJ9: =SUM(R6:AU6) -> 0 | AL9: 仕上 | AN9: =SUM(R7:AU7) -> 0 | AP9: 合計 | AR9: =SUM(R8:AU8) -> 0 | AZ9: 組前 | BB9: =SUM(AZ2:CD2) -> 0 | BD9: 組立 | BF9: =SUM(AZ3:CD3) -> 0 | BH9: 溶接 | BJ9: =SUM(AZ4:CD4) -> 0 | BL9: 歪取 | BN9: =SUM(AZ5:CD5) -> 0 | BP9: 塗装 | BR9: =SUM(AZ6:CD6) -> 0 | BT9: 仕上 | BV9: =SUM(AZ7:CD7) -> 0 | BX9: 合計 | BZ9: =SUM(AZ8:CD8) -> 0
P14: 28 | AV14: 29
R17: =SUM(R11:R16) -> 0 | S17: =SUM(S11:S16) -> 0 | T17: =SUM(T11:T16) -> 0 | U17: =SUM(U11:U16) -> 0 | V17: =SUM(V11:V16) -> 0 | W17: =SUM(W11:W16) -> 0 | X17: =SUM(X11:X16) -> 0 | Y17: =SUM(Y11:Y16) -> 0 | ... AS17: =SUM(AS11:AS16) -> 0 | AX17: =SUM(AX11:AX16) -> 0 | AY17: =SUM(AY11:AY16) -> 0 | AZ17: =SUM(AZ11:AZ16) -> 0 | BA17: =SUM(BA11:BA16) -> 0 | BB17: =SUM(BB11:BB16) -> 0 | BC17: =SUM(BC11:BC16) -> 0 | BD17: =SUM(BD11:BD16) -> 0 | BE17: =SUM(BE11:BE16) -> 0 | ... BZ17: =SUM(BZ11:BZ16) -> 0
R18: 組前 | T18: =SUM(R11:AS11) -> 0 | V18: 組立 | X18: =SUM(R12:AS12) -> 0 | Z18: 溶接 | AB18: =SUM(R13:AS13) -> 0 | AD18: 歪取 | AF18: =SUM(R14:AS14) -> 0 | AH18: 塗装 | AJ18: =SUM(R15:AS15) -> 0 | AL18: 仕上 | AN18: =SUM(R16:AS16) -> 0 | AP18: 合計 | AR18: =SUM(R17:AS17) -> 0 | AX18: 組前 | AZ18: =SUM(AX11:BZ11) -> 0 | BB18: 組立 | BD18: =SUM(AX12:BZ12) -> 0 | BF18: 溶接 | BH18: =SUM(AX13:BZ13) -> 0 | BJ18: 歪取 | BL18: =SUM(AX14:BZ14) -> 0 | BN18: 塗装 | BP18: =SUM(AX15:BZ15) -> 0 | BR18: 仕上 | BT18: =SUM(AX16:BZ16) -> 0 | BV18: 合計 | BX18: =SUM(AX17:BZ17) -> 0
A20: 箱型タイプ | H20: 組立前 | I20: =SUM(L20:BS20) -> 0.99520195 | L20: 0.0558 | M20: 0.094046914 | N20: 0.084694126 | O20: 0.099658586 | P20: 0.087312907 | Q20: 0.072161392 | S20: 0.087687018 | T20: 0.084132959 | U20: 0.061499214 | V20: 0.05289465 | W20: 0.050837037 | X20: 0.044477142 | Z20: 0.06 | AA20: 0.06
H21: 組立 | I21: =SUM(L21:BS21) -> 0.99923077 | Q21: 0.08 | X21: 0.04 | Z21: 0.08 | AA21: 0.08 | AB21: 0.08 | AC21: 0.08 | AD21: 0.04 | AG21: 0.08 | AH21: 0.049519231 | AI21: 0.069711538 | AJ21: 0.05 | AK21: 0.05 | AN21: 0.06 | AR21: 0.08 | AS21: 0.08
H22: 溶接 | I22: =SUM(L22:BS22) -> 1 | AA22: 0.04 | AB22: 0.09 | AC22: 0.09 | AD22: 0.09 | AE22: 0.09 | AG22: 0.07 | AH22: 0.09 | AI22: 0.09 | AJ22: 0.08 | AK22: 0.07 | AL22: 0.07 | AU22: 0.08 | AV22: 0.05
H23: 歪取り | I23: =SUM(L23:BS23) -> 1 | V23: 0.15 | W23: 0.15 | AP23: 0.15 | AQ23: 0.15 | AR23: 0.15 | AW23: 0.1 | AX23: 0.1 | AY23: 0.05
H24: 塗装 | I24: =SUM(L24:BS24) -> 1 | BD24: 0.05 | BE24: 0.2 | BF24: 0.2 | BG24: 0.2 | BI24: 0.13 | BJ24: 0.12 | BP24: 0.1
H25: 仕上げ | I25: =SUM(L25:BS25) -> 1 | AU25: 0.05 | AV25: 0.05 | AW25: 0.05 | AX25: 0.05 | AY25: 0.05 | AZ25: 0.05 | BB25: 0.05 | BC25: 0.05 | BD25: 0.05 | BG25: 0.05 | BI25: 0.05 | BJ25: 0.05 | BK25: 0.05 | BL25: 0.05 | BM25: 0.05 | BN25: 0.05 | BP25: 0.05 | BQ25: 0.05 | BR25: 0.05 | BS25: 0.05
L26: =SUM(L20:L25) -> 0.0558 | M26: =SUM(M20:M25) -> 0.094046914 | N26: =SUM(N20:N25) -> 0.084694126 | O26: =SUM(O20:O25) -> 0.099658586 | P26: =SUM(P20:P25) -> 0.087312907 | Q26: =SUM(Q20:Q25) -> 0.15216139 | R26: =SUM(R20:R25) -> 0 | S26: =SUM(S20:S25) -> 0.087687018 | ... BS26: =SUM(BS20:BS25) -> 0.05
H28: 20 | I28: t | J28: 月曜開始 | K28: 0.261 | L28: =$H$30*$K$28*L20 -> 11.815514 | M28: =$H$30*$K$28*M20 -> 19.914204 | N28: =$H$30*$K$28*N20 -> 17.933775 | O28: =$H$30*$K$28*O20 -> 21.102462 | P28: =$H$30*$K$28*P20 -> 18.488295 | Q28: =$H$30*$K$28*Q20 -> 15.279999 | R28: =$H$30*$K$28*R20 -> 0 | S28: =$H$30*$K$28*S20 -> 18.567512 | ... AA28: =$H$30*$K$28*AA20 -> 12.704854 | BW28: =SUM(L28:BV28) -> 210.73158
E29: 過去平均時間 | H29: 30 | I29: M | K29: 0.106 | L29: =$H$30*$K$29*L21 -> 0 | M29: =$H$30*$K$29*M21 -> 0 | N29: =$H$30*$K$29*N21 -> 0 | O29: =$H$30*$K$29*O21 -> 0 | P29: =$H$30*$K$29*P21 -> 0 | Q29: =$H$30*$K$29*Q21 -> 6.8797675 | R29: =$H$30*$K$29*R21 -> 0 | S29: =$H$30*$K$29*S21 -> 0 | ... AS29: =$H$30*$K$29*AS21 -> 6.8797675 | BW29: =SUM(L29:BV29) -> 85.930942
H30: =((H28/H29*1000)*-0.0107+47.698)*H28 -> 811.29333 | K30: 0.335 | L30: =$H$30*$K$30*L22 -> 0 | M30: =$H$30*$K$30*M22 -> 0 | N30: =$H$30*$K$30*N22 -> 0 | O30: =$H$30*$K$30*O22 -> 0 | P30: =$H$30*$K$30*P22 -> 0 | Q30: =$H$30*$K$30*Q22 -> 0 | R30: =$H$30*$K$30*R22 -> 0 | S30: =$H$30*$K$30*S22 -> 0 | ... BS30: =$H$30*$K$30*BS22 -> 0 | BW30: =SUM(L30:BV30) -> 271.78327
K31: 0.067 | L31: =$H$30*$K$31*L23 -> 0 | M31: =$H$30*$K$31*M23 -> 0 | N31: =$H$30*$K$31*N23 -> 0 | O31: =$H$30*$K$31*O23 -> 0 | P31: =$H$30*$K$31*P23 -> 0 | Q31: =$H$30*$K$31*Q23 -> 0 | R31: =$H$30*$K$31*R23 -> 0 | S31: =$H$30*$K$31*S23 -> 0 | ... BS31: =$H$30*$K$31*BS23 -> 0 | BW31: =SUM(L31:BV31) -> 54.356653
K32: 0.056 | L32: =$H$30*$K$32*L24 -> 0 | M32: =$H$30*$K$32*M24 -> 0 | N32: =$H$30*$K$32*N24 -> 0 | O32: =$H$30*$K$32*O24 -> 0 | P32: =$H$30*$K$32*P24 -> 0 | Q32: =$H$30*$K$32*Q24 -> 0 | R32: =$H$30*$K$32*R24 -> 0 | S32: =$H$30*$K$32*S24 -> 0 | ... BS32: =$H$30*$K$32*BS24 -> 0 | BW32: =SUM(L32:BV32) -> 45.432427
K33: 0.174 | L33: =$H$30*$K$33*L25 -> 0 | M33: =$H$30*$K$33*M25 -> 0 | N33: =$H$30*$K$33*N25 -> 0 | O33: =$H$30*$K$33*O25 -> 0 | P33: =$H$30*$K$33*P25 -> 0 | Q33: =$H$30*$K$33*Q25 -> 0 | R33: =$H$30*$K$33*R25 -> 0 | S33: =$H$30*$K$33*S25 -> 0 | ... BS33: =$H$30*$K$33*BS25 -> 7.058252 | BW33: =SUM(L33:BV33) -> 141.16504
A34: 過去平均 | B34: =G40 -> 369.98 | C34: 組立前 | D34: =SUM(EG45:WF45) -> 0 | E34: =SUM(D34/G34) -> 0 | G34: =G40*0.261 -> 96.56478 | BW34: =SUM(BW28:BW33) -> 809.39991
A35: 製造予定 | C35: 組立 | D35: =SUM(EG46:WF46) -> 0 | E35: =SUM(D35/G35) -> 0 | G35: =G40*0.106 -> 39.21788 | J35: 水曜開始 | K35: 0.261 | N35: =$H$30*$K$28*L20 -> 11.815514 | O35: =$H$30*$K$28*M20 -> 19.914204 | P35: =$H$30*$K$28*N20 -> 17.933775 | Q35: =$H$30*$K$28*O20 -> 21.102462 | S35: =$H$30*$K$28*P20 -> 18.488295 | T35: =$H$30*$K$28*Q20 -> 15.279999 | U35: =$H$30*$K$28*S20 -> 18.567512 | V35: =$H$30*$K$28*T20 -> 17.814949 | W35: =$H$30*$K$28*U20 -> 13.022309 | X35: =$H$30*$K$28*V20 -> 11.200313 | Z35: =$H$30*$K$28*W20 -> 10.764619 | AA35: =$H$30*$K$28*X20 -> 9.4179262 | AB35: =$H$30*$K$28*Z20 -> 12.704854 | AC35: =$H$30*$K$28*AA20 -> 12.704854 | BW35: =SUM(L35:BU35) -> 210.73158
A36: 営業予定 | C36: 溶接 | D36: =SUM(EG51:WF51) -> 0 | E36: =SUM(D36/G36) -> 0 | G36: =G40*0.332 -> 122.83336 | K36: 0.106 | N36: =$H$30*$K$29*L21 -> 0 | O36: =$H$30*$K$29*M21 -> 0 | P36: =$H$30*$K$29*N21 -> 0 | Q36: =$H$30*$K$29*O21 -> 0 | S36: =$H$30*$K$29*P21 -> 0 | T36: =$H$30*$K$29*Q21 -> 6.8797675 | U36: =$H$30*$K$29*S21 -> 0 | V36: =$H$30*$K$29*T21 -> 0 | W36: =$H$30*$K$29*U21 -> 0 | X36: =$H$30*$K$29*V21 -> 0 | Z36: =$H$30*$K$29*W21 -> 0 | AA36: =$H$30*$K$29*X21 -> 3.4398837 | AB36: =$H$30*$K$29*Z21 -> 6.8797675 | AC36: =$H$30*$K$29*AA21 -> 6.8797675 | AD36: =$H$30*$K$29*AB21 -> 6.8797675 | AE36: =$H$30*$K$29*AC21 -> 6.8797675 | AG36: =$H$30*$K$29*AD21 -> 3.4398837 | AH36: =$H$30*$K$29*AE21 -> 0 | AI36: =$H$30*$K$29*AG21 -> 6.8797675 | AJ36: =$H$30*$K$29*AH21 -> 4.2585099 | AK36: =$H$30*$K$29*AI21 -> 5.9949897 | AL36: =$H$30*$K$29*AJ21 -> 4.2998547 | AN36: =$H$30*$K$29*AK21 -> 4.2998547 | AO36: =$H$30*$K$29*AL21 -> 0 | AP36: =$H$30*$K$29*AN21 -> 5.1598256 | AQ36: =$H$30*$K$29*AO21 -> 0 | AR36: =$H$30*$K$29*AP21 -> 0 | AS36: =$H$30*$K$29*AQ21 -> 0 | AU36: =$H$30*$K$29*AR21 -> 6.8797675 | AV36: =$H$30*$K$29*AS21 -> 6.8797675 | AW36: =$H$30*$K$29*AU21 -> 0 | AX36: =$H$30*$K$29*AV21 -> 0 | AY36: =$H$30*$K$29*AW21 -> 0 | AZ36: =$H$30*$K$29*AX21 -> 0 | BB36: =$H$30*$K$29*AY21 -> 0 | BC36: =$H$30*$K$29*AZ21 -> 0 | BD36: =$H$30*$K$29*BB21 -> 0 | BE36: =$H$30*$K$29*BC21 -> 0 | BF36: =$H$30*$K$29*BD21 -> 0 | BG36: =$H$30*$K$29*BE21 -> 0 | BI36: =$H$30*$K$29*BF21 -> 0 | BJ36: =$H$30*$K$29*BG21 -> 0 | BK36: =$H$30*$K$29*BI21 -> 0 | BL36: =$H$30*$K$29*BJ21 -> 0 | BM36: =$H$30*$K$29*BK21 -> 0 | BN36: =$H$30*$K$29*BL21 -> 0 | BP36: =$H$30*$K$29*BM21 -> 0 | BQ36: =$H$30*$K$29*BN21 -> 0 | BR36: =$H$30*$K$29*BP21 -> 0 | BS36: =$H$30*$K$29*BQ21 -> 0 | BT36: =$H$30*$K$29*BR21 -> 0 | BU36: =$H$30*$K$29*BS21 -> 0 | BW36: =SUM(L36:BU36) -> 85.930942
B37: 実数時間 | C37: 歪取り | D37: =SUM(EG52:WF52) -> 0 | E37: =SUM(D37/G37) -> 0 | G37: =G40*0.068 -> 25.15864 | K37: 0.335 | N37: =$H$30*$K$30*L22 -> 0 | O37: =$H$30*$K$30*M22 -> 0 | P37: =$H$30*$K$30*N22 -> 0 | Q37: =$H$30*$K$30*O22 -> 0 | S37: =$H$30*$K$30*P22 -> 0 | T37: =$H$30*$K$30*Q22 -> 0 | U37: =$H$30*$K$30*S22 -> 0 | V37: =$H$30*$K$30*T22 -> 0 | W37: =$H$30*$K$30*U22 -> 0 | X37: =$H$30*$K$30*V22 -> 0 | Z37: =$H$30*$K$30*W22 -> 0 | AA37: =$H$30*$K$30*X22 -> 0 | AB37: =$H$30*$K$30*Z22 -> 0 | AC37: =$H$30*$K$30*AA22 -> 10.871331 | AD37: =$H$30*$K$30*AB22 -> 24.460494 | AE37: =$H$30*$K$30*AC22 -> 24.460494 | AG37: =$H$30*$K$30*AD22 -> 24.460494 | AH37: =$H$30*$K$30*AE22 -> 24.460494 | AI37: =$H$30*$K$30*AG22 -> 19.024829 | AJ37: =$H$30*$K$30*AH22 -> 24.460494 | AK37: =$H$30*$K$30*AI22 -> 24.460494 | AL37: =$H$30*$K$30*AJ22 -> 21.742661 | AN37: =$H$30*$K$30*AK22 -> 19.024829 | AO37: =$H$30*$K$30*AL22 -> 19.024829 | AP37: =$H$30*$K$30*AN22 -> 0 | AQ37: =$H$30*$K$30*AO22 -> 0 | AR37: =$H$30*$K$30*AP22 -> 0 | AS37: =$H$30*$K$30*AQ22 -> 0 | AU37: =$H$30*$K$30*AR22 -> 0 | AV37: =$H$30*$K$30*AS22 -> 0 | AW37: =$H$30*$K$30*AU22 -> 21.742661 | AX37: =$H$30*$K$30*AV22 -> 13.589163 | AY37: =$H$30*$K$30*AW22 -> 0 | AZ37: =$H$30*$K$30*AX22 -> 0 | BB37: =$H$30*$K$30*AY22 -> 0 | BC37: =$H$30*$K$30*AZ22 -> 0 | BD37: =$H$30*$K$30*BB22 -> 0 | BE37: =$H$30*$K$30*BC22 -> 0 | BF37: =$H$30*$K$30*BD22 -> 0 | BG37: =$H$30*$K$30*BE22 -> 0 | BI37: =$H$30*$K$30*BF22 -> 0 | BJ37: =$H$30*$K$30*BG22 -> 0 | BK37: =$H$30*$K$30*BI22 -> 0 | BL37: =$H$30*$K$30*BJ22 -> 0 | BM37: =$H$30*$K$30*BK22 -> 0 | BN37: =$H$30*$K$30*BL22 -> 0 | BP37: =$H$30*$K$30*BM22 -> 0 | BQ37: =$H$30*$K$30*BN22 -> 0 | BR37: =$H$30*$K$30*BP22 -> 0 | BS37: =$H$30*$K$30*BQ22 -> 0 | BT37: =$H$30*$K$30*BR22 -> 0 | BU37: =$H$30*$K$30*BS22 -> 0 | BW37: =SUM(L37:BU37) -> 271.78327
B38: =D40 -> 0 | C38: 塗装 | D38: =SUM(EG53:WF53) -> 0 | E38: =SUM(D38/G38) -> 0 | G38: =G40*0.059 -> 21.82882 | K38: 0.067 | N38: =$H$30*$K$31*L23 -> 0 | O38: =$H$30*$K$31*M23 -> 0 | P38: =$H$30*$K$31*N23 -> 0 | Q38: =$H$30*$K$31*O23 -> 0 | S38: =$H$30*$K$31*P23 -> 0 | T38: =$H$30*$K$31*Q23 -> 0 | U38: =$H$30*$K$31*S23 -> 0 | V38: =$H$30*$K$31*T23 -> 0 | W38: =$H$30*$K$31*U23 -> 0 | X38: =$H$30*$K$31*V23 -> 8.153498 | Z38: =$H$30*$K$31*W23 -> 8.153498 | AA38: =$H$30*$K$31*X23 -> 0 | AB38: =$H$30*$K$31*Z23 -> 0 | AC38: =$H$30*$K$31*AA23 -> 0 | AD38: =$H$30*$K$31*AB23 -> 0 | AE38: =$H$30*$K$31*AC23 -> 0 | AG38: =$H$30*$K$31*AD23 -> 0 | AH38: =$H$30*$K$31*AE23 -> 0 | AI38: =$H$30*$K$31*AG23 -> 0 | AJ38: =$H$30*$K$31*AH23 -> 0 | AK38: =$H$30*$K$31*AI23 -> 0 | AL38: =$H$30*$K$31*AJ23 -> 0 | AN38: =$H$30*$K$31*AK23 -> 0 | AO38: =$H$30*$K$31*AL23 -> 0 | AP38: =$H$30*$K$31*AN23 -> 0 | AQ38: =$H$30*$K$31*AO23 -> 0 | AR38: =$H$30*$K$31*AP23 -> 8.153498 | AS38: =$H$30*$K$31*AQ23 -> 8.153498 | AU38: =$H$30*$K$31*AR23 -> 8.153498 | AV38: =$H$30*$K$31*AS23 -> 0 | AW38: =$H$30*$K$31*AU23 -> 0 | AX38: =$H$30*$K$31*AV23 -> 0 | AY38: =$H$30*$K$31*AW23 -> 5.4356653 | AZ38: =$H$30*$K$31*AX23 -> 5.4356653 | BB38: =$H$30*$K$31*AY23 -> 2.7178327 | BC38: =$H$30*$K$31*AZ23 -> 0 | BD38: =$H$30*$K$31*BB23 -> 0 | BE38: =$H$30*$K$31*BC23 -> 0 | BF38: =$H$30*$K$31*BD23 -> 0 | BG38: =$H$30*$K$31*BE23 -> 0 | BI38: =$H$30*$K$31*BF23 -> 0 | BJ38: =$H$30*$K$31*BG23 -> 0 | BK38: =$H$30*$K$31*BI23 -> 0 | BL38: =$H$30*$K$31*BJ23 -> 0 | BM38: =$H$30*$K$31*BK23 -> 0 | BN38: =$H$30*$K$31*BL23 -> 0 | BP38: =$H$30*$K$31*BM23 -> 0 | BQ38: =$H$30*$K$31*BN23 -> 0 | BR38: =$H$30*$K$31*BP23 -> 0 | BS38: =$H$30*$K$31*BQ23 -> 0 | BT38: =$H$30*$K$31*BR23 -> 0 | BU38: =$H$30*$K$31*BS23 -> 0 | BW38: =SUM(L38:BU38) -> 54.356653
A39: 目標比率 | B39: =SUM(B38/(B34*E41/100)) -> #DIV/0! | C39: 仕上げ | D39: =SUM(EG54:WF54) -> 0 | E39: =SUM(D39/G39) -> 0 | G39: =G40*0.174 -> 64.37652 | K39: 0.056 | N39: =$H$30*$K$32*L24 -> 0 | O39: =$H$30*$K$32*M24 -> 0 | P39: =$H$30*$K$32*N24 -> 0 | Q39: =$H$30*$K$32*O24 -> 0 | S39: =$H$30*$K$32*P24 -> 0 | T39: =$H$30*$K$32*Q24 -> 0 | U39: =$H$30*$K$32*S24 -> 0 | V39: =$H$30*$K$32*T24 -> 0 | W39: =$H$30*$K$32*U24 -> 0 | X39: =$H$30*$K$32*V24 -> 0 | Z39: =$H$30*$K$32*W24 -> 0 | AA39: =$H$30*$K$32*X24 -> 0 | AB39: =$H$30*$K$32*Z24 -> 0 | AC39: =$H$30*$K$32*AA24 -> 0 | AD39: =$H$30*$K$32*AB24 -> 0 | AE39: =$H$30*$K$32*AC24 -> 0 | AG39: =$H$30*$K$32*AD24 -> 0 | AH39: =$H$30*$K$32*AE24 -> 0 | AI39: =$H$30*$K$32*AG24 -> 0 | AJ39: =$H$30*$K$32*AH24 -> 0 | AK39: =$H$30*$K$32*AI24 -> 0 | AL39: =$H$30*$K$32*AJ24 -> 0 | AN39: =$H$30*$K$32*AK24 -> 0 | AO39: =$H$30*$K$32*AL24 -> 0 | AP39: =$H$30*$K$32*AN24 -> 0 | AQ39: =$H$30*$K$32*AO24 -> 0 | AR39: =$H$30*$K$32*AP24 -> 0 | AS39: =$H$30*$K$32*AQ24 -> 0 | AU39: =$H$30*$K$32*AR24 -> 0 | AV39: =$H$30*$K$32*AS24 -> 0 | AW39: =$H$30*$K$32*AU24 -> 0 | AX39: =$H$30*$K$32*AV24 -> 0 | AY39: =$H$30*$K$32*AW24 -> 0 | AZ39: =$H$30*$K$32*AX24 -> 0 | BB39: =$H$30*$K$32*AY24 -> 0 | BC39: =$H$30*$K$32*AZ24 -> 0 | BD39: =$H$30*$K$32*BB24 -> 0 | BE39: =$H$30*$K$32*BC24 -> 0 | BF39: =$H$30*$K$32*BD24 -> 2.2716213 | BG39: =$H$30*$K$32*BE24 -> 9.0864853 | BI39: =$H$30*$K$32*BF24 -> 9.0864853 | BJ39: =$H$30*$K$32*BG24 -> 9.0864853 | BK39: =$H$30*$K$32*BI24 -> 5.9062155 | BL39: =$H$30*$K$32*BJ24 -> 5.4518912 | BM39: =$H$30*$K$32*BK24 -> 0 | BN39: =$H$30*$K$32*BL24 -> 0 | BP39: =$H$30*$K$32*BM24 -> 0 | BQ39: =$H$30*$K$32*BN24 -> 0 | BR39: =$H$30*$K$32*BP24 -> 4.5432427 | BS39: =$H$30*$K$32*BQ24 -> 0 | BT39: =$H$30*$K$32*BR24 -> 0 | BU39: =$H$30*$K$32*BS24 -> 0 | BW39: =SUM(L39:BU39) -> 45.432427
A40: 目標比率 | B40: =SUM(B38/(B35*E41/100)) -> #DIV/0! | C40: 小計 | D40: =SUM(EG55:WF55) -> 0 | E40: 10 | G40: =((E40/F41*1000)*-0.0107+47.698)*E40 -> 369.98 | K40: 0.174 | N40: =$H$30*$K$33*L25 -> 0 | O40: =$H$30*$K$33*M25 -> 0 | P40: =$H$30*$K$33*N25 -> 0 | Q40: =$H$30*$K$33*O25 -> 0 | S40: =$H$30*$K$33*P25 -> 0 | T40: =$H$30*$K$33*Q25 -> 0 | U40: =$H$30*$K$33*S25 -> 0 | V40: =$H$30*$K$33*T25 -> 0 | W40: =$H$30*$K$33*U25 -> 0 | X40: =$H$30*$K$33*V25 -> 0 | Z40: =$H$30*$K$33*W25 -> 0 | AA40: =$H$30*$K$33*X25 -> 0 | AB40: =$H$30*$K$33*Z25 -> 0 | AC40: =$H$30*$K$33*AA25 -> 0 | AD40: =$H$30*$K$33*AB25 -> 0 | AE40: =$H$30*$K$33*AC25 -> 0 | AG40: =$H$30*$K$33*AD25 -> 0 | AH40: =$H$30*$K$33*AE25 -> 0 | AI40: =$H$30*$K$33*AG25 -> 0 | AJ40: =$H$30*$K$33*AH25 -> 0 | AK40: =$H$30*$K$33*AI25 -> 0 | AL40: =$H$30*$K$33*AJ25 -> 0 | AN40: =$H$30*$K$33*AK25 -> 0 | AO40: =$H$30*$K$33*AL25 -> 0 | AP40: =$H$30*$K$33*AN25 -> 0 | AQ40: =$H$30*$K$33*AO25 -> 0 | AR40: =$H$30*$K$33*AP25 -> 0 | AS40: =$H$30*$K$33*AQ25 -> 0 | AU40: =$H$30*$K$33*AR25 -> 0 | AV40: =$H$30*$K$33*AS25 -> 0 | AW40: =$H$30*$K$33*AU25 -> 7.058252 | AX40: =$H$30*$K$33*AV25 -> 7.058252 | AY40: =$H$30*$K$33*AW25 -> 7.058252 | AZ40: =$H$30*$K$33*AX25 -> 7.058252 | BB40: =$H$30*$K$33*AY25 -> 7.058252 | BC40: =$H$30*$K$33*AZ25 -> 7.058252 | BD40: =$H$30*$K$33*BB25 -> 7.058252 | BE40: =$H$30*$K$33*BC25 -> 7.058252 | BF40: =$H$30*$K$33*BD25 -> 7.058252 | BG40: =$H$30*$K$33*BE25 -> 0 | BI40: =$H$30*$K$33*BF25 -> 0 | BJ40: =$H$30*$K$33*BG25 -> 7.058252 | BK40: =$H$30*$K$33*BI25 -> 7.058252 | BL40: =$H$30*$K$33*BJ25 -> 7.058252 | BM40: =$H$30*$K$33*BK25 -> 7.058252 | BN40: =$H$30*$K$33*BL25 -> 7.058252 | BP40: =$H$30*$K$33*BM25 -> 7.058252 | BQ40: =$H$30*$K$33*BN25 -> 7.058252 | BR40: =$H$30*$K$33*BP25 -> 7.058252 | BS40: =$H$30*$K$33*BQ25 -> 7.058252 | BT40: =$H$30*$K$33*BR25 -> 7.058252 | BU40: =$H$30*$K$33*BS25 -> 7.058252 | BW40: =SUM(L40:BU40) -> 141.16504
A41: 目標比率 | B41: =SUM(B38/(B36*E41/100)) -> #DIV/0! | C41: =SUM(B38/(E40*E41/100)) -> #DIV/0! | D41: H | E41: 0 | F41: 10 | BW41: =SUM(BW35:BW40) -> 809.39991
H43: 製作日数 | L43: 1 | M43: 2 | N43: 3 | O43: 4 | P43: 5 | Q43: 6 | R43: 7 | S43: 8 | T43: 9 | U43: 10 | V43: 11 | W43: 12 | X43: 13 | Y43: 14 | Z43: 15 | AA43: 16 | AB43: 17 | AC43: 18 | AD43: 19 | AE43: 20 | AF43: 21 | AG43: 22 | AH43: 23 | AI43: 24 | AJ43: 25 | AK43: 26 | AL43: 27 | AM43: 28 | AN43: 29 | AO43: 30 | AP43: 31 | AQ43: 32 | AR43: 33 | AS43: 34 | AT43: 35 | AU43: 36 | AV43: 37 | AW43: 38 | AX43: 39 | AY43: 40 | AZ43: 41 | BA43: 42 | BB43: 43 | BC43: 44 | BD43: 45 | BE43: 46 | BF43: 47 | BG43: 48 | BH43: 49 | BI43: 50 | BJ43: 51 | BK43: 52 | BL43: 53 | BM43: 54 | BN43: 55 | BO43: 56 | BP43: 57 | BQ43: 58 | BR43: 59 | BS43: 60 | BT43: 61 | BU43: 62 | BV43: 63 | BW43: 64 | BX43: 65 | BY43: 66 | BZ43: 67 | CA43: 68 | CB43: 69 | CC43: 70 | CD43: 71 | CE43: 72 | CF43: 73 | CG43: 74 | CH43: 75
H44: 箱タイプ(BoX型)60日 | L44: 罫書 | M44: 罫書切断 | N44: 罫書切断 | O44: 罫書桁孔 | P44: 開先仕上 | Q44: 削り仕上 | S44: 継W | T44: 継W溝出 | U44: UT検？ | V44: ２R | W44: 逆歪削り | X44: 逆歪削り | Z44: 仕上げ | AA44: 仕上げ | AB44: 箱組 | AC44: 箱W | AD44: 箱WF組 | AE44: 箱WF組 | AG44: FW | AH44: FW | AI44: FWRW | AJ44: FWRW | AK44: RW | AL44: RW | AN44: スタッド | AO44: 歪取 | AP44: 歪取 | AQ44: 歪取 | AR44: 地覆組W | AS44: 地覆組W | AU44: 地覆組W | AV44: 地覆組W | AW44: 櫛歪 | AX44: 櫛歪 | AY44: 櫛歪 | AZ44: 仕上げ | BB44: 仕上げ | BC44: ブラスト | BD44: 戻り | BE44: 塗装 | BF44: 塗装 | BG44: 塗装 | BI44: 塗装 | BJ44: 塗装 | BK44: SET？ | BL44: ニタ乾？ | BM44: 圧縮 | BN44: 仕上げ | BP44: 仕上げ | BQ44: 仕上げ | BR44: 仕上げ | BS44: 完成検査
N45: 1 | O45: 2 | P45: 3 | Q45: 4 | R45: 5 | S45: 6 | T45: 7 | U45: 8 | V45: 9 | W45: 10 | X45: 11 | Y45: 12 | Z45: 13 | AA45: 14 | AB45: 15 | AC45: 16 | AD45: 17 | AE45: 18 | AF45: 19 | AG45: 20 | AH45: 21 | AI45: 22 | AJ45: 23 | AK45: 24 | AL45: 25 | AM45: 26 | AN45: 27 | AO45: 28 | AP45: 29 | AQ45: 30 | AR45: 31 | AS45: 32 | AT45: 33 | AU45: 34 | AV45: 35 | AW45: 36 | AX45: 37 | AY45: 38 | AZ45: 39 | BA45: 40 | BB45: 41 | BC45: 42 | BD45: 43 | BE45: 44 | BF45: 45 | BG45: 46 | BH45: 47 | BI45: 48 | BJ45: 49 | BK45: 50 | BL45: 51 | BM45: 52 | BN45: 53 | BO45: 54 | BP45: 55 | BQ45: 56 | BR45: 57 | BS45: 58 | BT45: 59 | BU45: 60 | BV45: 61 | BW45: 62 | BX45: 63 | BY45: 64 | BZ45: 65 | CA45: 66 | CB45: 67 | CC45: 68 | CD45: 69 | CE45: 70 | CF45: 71 | CG45: 72 | CH45: 73 | CI45: 74 | CJ45: 75
N46: 罫書 | O46: 罫書切断 | P46: 罫書切断 | Q46: 罫書桁孔 | S46: 開先仕上 | T46: 削り仕上 | U46: 継W | V46: 継W溝出 | W46: UT検？ | X46: ２R | Z46: 逆歪削り | AA46: 逆歪削り | AB46: 仕上げ | AC46: 仕上げ | AD46: 箱組 | AE46: 箱W | AG46: 箱WF組 | AH46: 箱WF組 | AI46: FW | AJ46: FW | AK46: FWRW | AL46: FWRW | AN46: RW | AO46: RW | AP46: スタッド | AQ46: 歪取 | AR46: 歪取 | AS46: 歪取 | AU46: 地覆組W | AV46: 地覆組W | AW46: 地覆組W | AX46: 地覆組W | AY46: 櫛歪 | AZ46: 櫛歪 | BB46: 櫛歪 | BC46: 仕上げ | BD46: 仕上げ | BE46: ブラスト | BF46: 戻り | BG46: 塗装 | BI46: 塗装 | BJ46: 塗装 | BK46: 塗装 | BL46: 塗装 | BM46: SET？ | BN46: ニタ乾？ | BP46: 圧縮 | BQ46: 仕上げ | BR46: 仕上げ | BS46: 仕上げ | BT46: 仕上げ | BU46: 完成検査
H47: 製作日数 | L47: 1 | M47: 2 | N47: 3 | O47: 4 | P47: 5 | Q47: 6 | R47: 7 | S47: 8 | T47: 9 | U47: 10 | V47: 11 | W47: 12 | X47: 13 | Y47: 14 | Z47: 15 | AA47: 16 | AB47: 17 | AC47: 18 | AD47: 19 | AE47: 20 | AF47: 21 | AG47: 22 | AH47: 23 | AI47: 24 | AJ47: 25 | AK47: 26 | AL47: 27 | AM47: 28 | AN47: 29 | AO47: 30 | AP47: 31 | AQ47: 32 | AR47: 33 | AS47: 34 | AT47: 35 | AU47: 36 | AV47: 37 | AW47: 38 | AX47: 39 | AY47: 40 | AZ47: 41 | BA47: 42 | BB47: 43 | BC47: 44 | BD47: 45 | BE47: 46 | BF47: 47 | BG47: 48 | BH47: 49 | BI47: 50 | BJ47: 51 | BK47: 52 | BL47: 53 | BM47: 54 | BN47: 55 | BO47: 56 | BP47: 57 | BQ47: 58 | BR47: 59 | BS47: 60 | BT47: 61 | BU47: 62 | BV47: 63 | BW47: 64 | BX47: 65 | BY47: 66 | BZ47: 67 | CA47: 68 | CB47: 69 | CC47: 70 | CD47: 71 | CE47: 72 | CF47: 73 | CG47: 74 | CH47: 75 | CI47: 76 | CJ47: 77 | CK47: 78 | CL47: 79 | CM47: 80 | CN47: 81 | CO47: 82 | CP47: 83 | CQ47: 84 | CR47: 85 | CS47: 86 | CT47: 87 | CU47: 88 | CV47: 89 | CW47: 90 | CX47: 91
H48: 箱タイプ(BoX型)90日 土日休み | L48: 罫書 | M48: 罫書切断 | N48: 罫書切断 | O48: 罫書桁孔 | P48: 開先仕上 | S48: 削り仕上 | T48: 継W | U48: 継W溝出 | V48: UT検？ | W48: ２R？ | Z48: 逆歪削り | AA48: 逆歪削り | AB48: 仕上げ | AC48: 仕上げ | AD48: 仕上げ | AG48: 仕上げ | AH48: 仕上げ | AI48: 箱組 | AJ48: 箱W | AK48: 箱WF組 | AN48: 箱WF組 | AO48: FW | AP48: FW | AQ48: FWRW | AR48: FWRW | AU48: FWRW | AV48: FWRW | AW48: RW | AX48: RW | AY48: スタッド | BB48: 歪取 | BC48: 歪取 | BD48: 歪取 | BE48: 歪取 | BF48: 地覆組W | BI48: 地覆組W | BJ48: 地覆組W | BK48: 櫛歪 | BL48: 櫛歪 | BM48: 櫛歪 | BP48: 仕上げ | BQ48: 仕上げ | BR48: 仕上げ | BS48: 仕上げ | BT48: 仕上げ | BW48: 仕上げ | BX48: ブラスト | BY48: ブラスト | BZ48: 戻り | CA48: 塗装 | CD48: 塗装 | CE48: 塗装 | CF48: 塗装 | CG48: 塗装 | CH48: 塗装 | CK48: 塗装 | CL48: SET？ | CM48: ニタ乾？ | CN48: ニタ乾？ | CO48: 圧縮 | CR48: 仕上げ | CS48: 仕上げ | CT48: 仕上げ | CU48: 仕上げ | CV48: 完成検査
N49: 1 | O49: 2 | P49: 3 | Q49: 4 | R49: 5 | S49: 6 | T49: 7 | U49: 8 | V49: 9 | W49: 10 | X49: 11 | Y49: 12 | Z49: 13 | AA49: 14 | AB49: 15 | AC49: 16 | AD49: 17 | AE49: 18 | AF49: 19 | AG49: 20 | AH49: 21 | AI49: 22 | AJ49: 23 | AK49: 24 | AL49: 25 | AM49: 26 | AN49: 27 | AO49: 28 | AP49: 29 | AQ49: 30 | AR49: 31 | AS49: 32 | AT49: 33 | AU49: 34 | AV49: 35 | AW49: 36 | AX49: 37 | AY49: 38 | AZ49: 39 | BA49: 40 | BB49: 41 | BC49: 42 | BD49: 43 | BE49: 44 | BF49: 45 | BG49: 46 | BH49: 47 | BI49: 48 | BJ49: 49 | BK49: 50 | BL49: 51 | BM49: 52 | BN49: 53 | BO49: 54 | BP49: 55 | BQ49: 56 | BR49: 57 | BS49: 58 | BT49: 59 | BU49: 60 | BV49: 61 | BW49: 62 | BX49: 63 | BY49: 64 | BZ49: 65 | CA49: 66 | CB49: 67 | CC49: 68 | CD49: 69 | CE49: 70 | CF49: 71 | CG49: 72 | CH49: 73 | CI49: 74 | CJ49: 75 | CK49: 76 | CL49: 77 | CM49: 78 | CN49: 79 | CO49: 80 | CP49: 81 | CQ49: 82 | CR49: 83 | CS49: 84 | CT49: 85 | CU49: 86 | CV49: 87 | CW49: 88 | CX49: 89 | CY49: 90
N50: 罫書 | O50: 罫書切断 | P50: 罫書切断 | S50: 罫書桁孔 | T50: 開先仕上 | U50: 削り仕上 | V50: 継W | W50: 継W溝出 | Z50: UT検？ | AA50: ２R？ | AB50: 逆歪削り | AC50: 逆歪削り | AD50: 仕上げ | AG50: 仕上げ | AH50: 仕上げ | AI50: 仕上げ | AJ50: 仕上げ | AK50: 箱組 | AN50: 箱W | AO50: 箱WF組 | AP50: 箱WF組 | AQ50: FW | AR50: FW | AU50: FWRW | AV50: FWRW | AW50: FWRW | AX50: FWRW | AY50: RW | BB50: RW | BC50: スタッド | BD50: 歪取 | BE50: 歪取 | BF50: 歪取 | BI50: 歪取 | BJ50: 地覆組W | BK50: 地覆組W | BL50: 地覆組W | BM50: 櫛歪 | BP50: 櫛歪 | BQ50: 櫛歪 | BR50: 仕上げ | BS50: 仕上げ | BT50: 仕上げ | BW50: 仕上げ | BX50: 仕上げ | BY50: 仕上げ | BZ50: ブラスト | CA50: ブラスト | CD50: 戻り | CE50: 塗装 | CF50: 塗装 | CG50: 塗装 | CH50: 塗装 | CK50: 塗装 | CL50: 塗装 | CM50: 塗装 | CN50: SET？ | CO50: ニタ乾？ | CR50: ニタ乾？ | CS50: 圧縮 | CT50: 仕上げ | CU50: 仕上げ | CV50: 仕上げ | CY50: 仕上げ | CZ50: 完成検査
H59: 製作日数 | L59: 1 | M59: 2 | N59: 3 | O59: 4 | P59: 5 | Q59: 6 | R59: 7 | S59: 8 | T59: 9 | U59: 10 | V59: 11 | W59: 12 | X59: 13 | Y59: 14 | Z59: 15 | AA59: 16 | AB59: 17 | AC59: 18 | AD59: 19 | AE59: 20 | AF59: 21 | AG59: 22 | AH59: 23 | AI59: 24 | AJ59: 25 | AK59: 26 | AL59: 27 | AM59: 28 | AN59: 29 | AO59: 30 | AP59: 31 | AQ59: 32 | AR59: 33 | AS59: 34 | AT59: 35 | AU59: 36 | AV59: 37 | AW59: 38 | AX59: 39 | AY59: 40
H60: 標準タイプ(I型) 10ｔ以下 | L60: 罫書 | M60: 罫書切断 | N60: 罫書切断 | O60: 仕上げ | P60: 削り板継 | Q60: 削り板継 | S60: UT検査 | T60: 小組 | U60: 小組W | V60: 小W | W60: 小W | X60: 小W歪 | Z60: 小歪 | AA60: 小歪 | AB60: 大組 | AC60: 大組W | AD60: 大組W | AE60: 大W | AG60: 大W | AH60: スタッド | AI60: 歪取仕上 | AJ60: 歪取仕上 | AK60: 歪取仕上 | AL60: ブラスト | AN60: 戻り | AO60: 塗装 | AP60: 塗装 | AQ60: 塗装 | AS60: シール | AU60: 圧縮 | AV60: 仕上げ | AW60: 仕上げ | AX60: 仕上げ | AY60: 完成検査
H61: 進捗％（目安） | O61: 10 | U61: 30 | AA61: 50 | AE61: 70 | AJ61: 80 | AP61: 90
N62: 罫書 | O62: 罫書切断 | P62: 罫書切断 | Q62: 仕上げ | S62: 削り板継 | T62: 削り板継 | U62: UT検査 | V62: 小組 | W62: 小組W | X62: 小W | Z62: 小W | AA62: 小W歪 | AB62: 小歪 | AC62: 小歪 | AD62: 大組 | AE62: 大組W | AG62: 大組W | AH62: 大W | AI62: 大W | AJ62: スタッド | AK62: 歪取仕上 | AL62: 歪取仕上 | AN62: 歪取仕上 | AO62: ブラスト | AP62: 戻り | AQ62: 塗装 | AR62: 塗装 | AS62: 塗装 | AU62: シール | AV62: 圧縮 | AW62: 仕上げ | AX62: 仕上げ | AY62: 仕上げ | AZ62: 完成検査
...

Sheet 実績と3ヵ月予報
NV2: 2 | NW2: 0 | NX2: 2 | NY2: 5 | ABW2: 2 | ABX2: 0 | ABY2: 2 | ABZ2: 6
I3: 休 | J3: 会 | T3: 1 | AY3: 2 | CB3: 3 | DG3: 4 | EK3: 5 | FP3: 6 | GT3: 7 | HY3: 8 | JD3: 9 | KH3: 10 | LM3: 11 | MQ3: 12 | NV3: 1 | PA3: 2 | QC3: 3 | RH3: 4 | SL3: 5 | TQ3: 6 | UU3: 7 | VZ3: 8 | XE3: 9 | YI3: 10 | ZN3: 11 | AAR3: 12 | ABW3: 1 | ADB3: 2 | AED3: 3 | AFI3: 4 | AGM3: 5 | AHR3: 6 | AIV3: 7 | AKA3: 8 | ALF3: 9 | AMJ3: 10 | ANO3: 11 | AOS3: 12
B4: 客先 | C4: 工事名 | E4: 詳細 | I4: 21 | J4: 22 | K4: 23 | L4: 24 | M4: 25 | N4: 26 | O4: 27 | P4: 28 | Q4: 29 | R4: 30 | S4: 31 | T4: 1 | U4: 2 | V4: 3 | W4: 4 | X4: 5 | Y4: 6 | Z4: 7 | AA4: 8 | AB4: 9 | AC4: 10 | AD4: 11 | AE4: 12 | AF4: 13 | AG4: 14 | AH4: 15 | AI4: 16 | AJ4: 17 | AK4: 18 | AL4: 19 | AM4: 20 | AN4: 21 | AO4: 22 | AP4: 23 | AQ4: 24 | AR4: 25 | AS4: 26 | AT4: 27 | AU4: 28 | AV4: 29 | AW4: 30 | AX4: 31 | AY4: 1 | AZ4: 2 | BA4: 3 | BB4: 4 | BC4: 5 | BD4: 6 | BE4: 7 | BF4: 8 | BG4: 9 | BH4: 10 | BI4: 11 | BJ4: 12 | BK4: 13 | BL4: 14 | BM4: 15 | BN4: 16 | BO4: 17 | BP4: 18 | BQ4: 19 | BR4: 20 | BS4: 21 | BT4: 22 | BU4: 23 | BV4: 24 | BW4: 25 | BX4: 26 | BY4: 27 | BZ4: 28 | CA4: 29 | CB4: 1 | CC4: 2 | CD4: 3 | CE4: 4 | CF4: 5 | CG4: 6 | CH4: 7 | CI4: 8 | CJ4: 9 | CK4: 10 | CL4: 11 | CM4: 12 | CN4: 13 | CO4: 14 | CP4: 15 | CQ4: 16 | CR4: 17 | CS4: 18 | CT4: 19 | CU4: 20 | CV4: 21 | CW4: 22 | CX4: 23 | CY4: 24 | CZ4: 25 | DA4: 26 | DB4: 27 | DC4: 28 | DD4: 29 | DE4: 30 | DF4: 31 | DG4: 1 | DH4: 2 | DI4: 3 | DJ4: 4 | DK4: 5 | DL4: 6 | DM4: 7 | DN4: 8 | DO4: 9 | DP4: 10 | DQ4: 11 | DR4: 12 | DS4: 13 | DT4: 14 | DU4: 15 | DV4: 16 | DW4: 17 | DX4: 18 | DY4: 19 | DZ4: 20 | EA4: 21 | EB4: 22 | EC4: 23 | ED4: 24 | EE4: 25 | EF4: 26 | EG4: 27 | EH4: 28 | EI4: 29 | EJ4: 30 | EK4: 1 | EL4: 2 | EM4: 3 | EN4: 4 | EO4: 5 | EP4: 6 | EQ4: 7 | ER4: 8 | ES4: 9 | ET4: 10 | EU4: 11 | EV4: 12 | EW4: 13 | EX4: 14 | EY4: 15 | EZ4: 16 | FA4: 17 | FB4: 18 | FC4: 19 | FD4: 20 | FE4: 21 | FF4: 22 | FG4: 23 | FH4: 24 | FI4: 25 | FJ4: 26 | FK4: 27 | FL4: 28 | FM4: 29 | FN4: 30 | FO4: 31 | FP4: 1 | FQ4: 2 | FR4: 3 | FS4: 4 | FT4: 5 | FU4: 6 | FV4: 7 | FW4: 8 | FX4: 9 | FY4: 10 | FZ4: 11 | GA4: 12 | GB4: 13 | GC4: 14 | GD4: 15 | GE4: 16 | GF4: 17 | GG4: 18 | GH4: 19 | GI4: 20 | GJ4: 21 | GK4: 22 | GL4: 23 | GM4: 24 | GN4: 25 | GO4: 26 | GP4: 27 | GQ4: 28 | GR4: 29 | GS4: 30 | GT4: 1 | GU4: 2 | GV4: 3 | GW4: 4 | GX4: 5 | GY4: 6 | GZ4: 7 | HA4: 8 | HB4: 9 | HC4: 10 | HD4: 11 | HE4: 12 | HF4: 13 | HG4: 14 | HH4: 15 | HI4: 16 | HJ4: 17 | HK4: 18 | HL4: 19 | HM4: 20 | HN4: 21 | HO4: 22 | HP4: 23 | HQ4: 24 | HR4: 25 | HS4: 26 | HT4: 27 | HU4: 28 | HV4: 29 | HW4: 30 | HX4: 31 | HY4: 1 | HZ4: 2 | IA4: 3 | IB4: 4 | IC4: 5 | ID4: 6 | IE4: 7 | IF4: 8 | IG4: 9 | IH4: 10 | II4: 11 | IJ4: 12 | IK4: 13 | IL4: 14 | IM4: 15 | IN4: 16 | IO4: 17 | IP4: 18 | IQ4: 19 | IR4: 20 | IS4: 21 | IT4: 22 | IU4: 23 | IV4: 24 | IW4: 25 | IX4: 26 | IY4: 27 | IZ4: 28 | JA4: 29 | JB4: 30 | JC4: 31 | JD4: 1 | JE4: 2 | JF4: 3 | JG4: 4 | JH4: 5 | JI4: 6 | JJ4: 7 | JK4: 8 | JL4: 9 | JM4: 10 | JN4: 11 | JO4: 12 | JP4: 13 | JQ4: 14 | JR4: 15 | JS4: 16 | JT4: 17 | JU4: 18 | JV4: 19 | JW4: 20 | JX4: 21 | JY4: 22 | JZ4: 23 | KA4: 24 | KB4: 25 | KC4: 26 | KD4: 27 | KE4: 28 | KF4: 29 | KG4: 30 | KH4: 1 | KI4: 2 | KJ4: 3 | KK4: 4 | KL4: 5 | KM4: 6 | KN4: 7 | KO4: 8 | KP4: 9 | KQ4: 10 | KR4: 11 | KS4: 12 | KT4: 13 | KU4: 14 | KV4: 15 | KW4: 16 | KX4: 17 | KY4: 18 | KZ4: 19 | LA4: 20 | LB4: 21 | LC4: 22 | LD4: 23 | LE4: 24 | LF4: 25 | LG4: 26 | LH4: 27 | LI4: 28 | LJ4: 29 | LK4: 30 | LL4: 31 | LM4: 1 | LN4: 2 | LO4: 3 | LP4: 4 | LQ4: 5 | LR4: 6 | LS4: 7 | LT4: 8 | LU4: 9 | LV4: 10 | LW4: 11 | LX4: 12 | LY4: 13 | LZ4: 14 | MA4: 15 | MB4: 16 | MC4: 17 | MD4: 18 | ME4: 19 | MF4: 20 | MG4: 21 | MH4: 22 | MI4: 23 | MJ4: 24 | MK4: 25 | ML4: 26 | MM4: 27 | MN4: 28 | MO4: 29 | MP4: 30 | MQ4: 1 | MR4: 2 | MS4: 3 | MT4: 4 | MU4: 5 | MV4: 6 | MW4: 7 | MX4: 8 | MY4: 9 | MZ4: 10 | NA4: 11 | NB4: 12 | NC4: 13 | ND4: 14 | NE4: 15 | NF4: 16 | NG4: 17 | NH4: 18 | NI4: 19 | NJ4: 20 | NK4: 21 | NL4: 22 | NM4: 23 | NN4: 24 | NO4: 25 | NP4: 26 | NQ4: 27 | NR4: 28 | NS4: 29 | NT4: 30 | NU4: 31 | NV4: 1 | NW4: 2 | NX4: 3 | NY4: 4 | NZ4: 5 | OA4: 6 | OB4: 7 | OC4: 8 | OD4: 9 | OE4: 10 | OF4: 11 | OG4: 12 | OH4: 13 | OI4: 14 | OJ4: 15 | OK4: 16 | OL4: 17 | OM4: 18 | ON4: 19 | OO4: 20 | OP4: 21 | OQ4: 22 | OR4: 23 | OS4: 24 | OT4: 25 | OU4: 26 | OV4: 27 | OW4: 28 | OX4: 29 | OY4: 30 | OZ4: 31 | PA4: 1 | PB4: 2 | PC4: 3 | PD4: 4 | PE4: 5 | PF4: 6 | PG4: 7 | PH4: 8 | PI4: 9 | PJ4: 10 | PK4: 11 | PL4: 12 | PM4: 13 | PN4: 14 | PO4: 15 | PP4: 16 | PQ4: 17 | PR4: 18 | PS4: 19 | PT4: 20 | PU4: 21 | PV4: 22 | PW4: 23 | PX4: 24 | PY4: 25 | PZ4: 26 | QA4: 27 | QB4: 28 | QC4: 1 | QD4: 2 | QE4: 3 | QF4: 4 | QG4: 5 | QH4: 6 | QI4: 7 | QJ4: 8 | QK4: 9 | QL4: 10 | QM4: 11 | QN4: 12 | QO4: 13 | QP4: 14 | QQ4: 15 | QR4: 16 | QS4: 17 | QT4: 18 | QU4: 19 | QV4: 20 | QW4: 21 | QX4: 22 | QY4: 23 | QZ4: 24 | RA4: 25 | RB4: 26 | RC4: 27 | RD4: 28 | RE4: 29 | RF4: 30 | RG4: 31 | RH4: 1 | RI4: 2 | RJ4: 3 | RK4: 4 | RL4: 5 | RM4: 6 | RN4: 7 | RO4: 8 | RP4: 9 | RQ4: 10 | RR4: 11 | RS4: 12 | RT4: 13 | RU4: 14 | RV4: 15 | RW4: 16 | RX4: 17 | RY4: 18 | RZ4: 19 | SA4: 20 | SB4: 21 | SC4: 22 | SD4: 23 | SE4: 24 | SF4: 25 | SG4: 26 | SH4: 27 | SI4: 28 | SJ4: 29 | SK4: 30 | SL4: 1 | SM4: 2 | SN4: 3 | SO4: 4 | SP4: 5 | SQ4: 6 | SR4: 7 | SS4: 8 | ST4: 9 | SU4: 10 | SV4: 11 | SW4: 12 | SX4: 13 | SY4: 14 | SZ4: 15 | TA4: 16 | TB4: 17 | TC4: 18 | TD4: 19 | TE4: 20 | TF4: 21 | TG4: 22 | TH4: 23 | TI4: 24 | TJ4: 25 | TK4: 26 | TL4: 27 | TM4: 28 | TN4: 29 | TO4: 30 | TP4: 31 | TQ4: 1 | TR4: 2 | TS4: 3 | TT4: 4 | TU4: 5 | TV4: 6 | TW4: 7 | TX4: 8 | TY4: 9 | TZ4: 10 | UA4: 11 | UB4: 12 | UC4: 13 | UD4: 14 | UE4: 15 | UF4: 16 | UG4: 17 | UH4: 18 | UI4: 19 | UJ4: 20 | UK4: 21 | UL4: 22 | UM4: 23 | UN4: 24 | UO4: 25 | UP4: 26 | UQ4: 27 | UR4: 28 | US4: 29 | UT4: 30 | UU4: 1 | UV4: 2 | UW4: 3 | UX4: 4 | UY4: 5 | UZ4: 6 | VA4: 7 | VB4: 8 | VC4: 9 | VD4: 10 | VE4: 11 | VF4: 12 | VG4: 13 | VH4: 14 | VI4: 15 | VJ4: 16 | VK4: 17 | VL4: 18 | VM4: 19 | VN4: 20 | VO4: 21 | VP4: 22 | VQ4: 23 | VR4: 24 | VS4: 25 | VT4: 26 | VU4: 27 | VV4: 28 | VW4: 29 | VX4: 30 | VY4: 31 | VZ4: 1 | WA4: 2 | WB4: 3 | WC4: 4 | WD4: 5 | WE4: 6 | WF4: 7 | WG4: 8 | WH4: 9 | WI4: 10 | WJ4: 11 | WK4: 12 | WL4: 13 | WM4: 14 | WN4: 15 | WO4: 16 | WP4: 17 | WQ4: 18 | WR4: 19 | WS4: 20 | WT4: 21 | WU4: 22 | WV4: 23 | WW4: 24 | WX4: 25 | WY4: 26 | WZ4: 27 | XA4: 28 | XB4: 29 | XC4: 30 | XD4: 31 | XE4: 1 | XF4: 2 | XG4: 3 | XH4: 4 | XI4: 5 | XJ4: 6 | XK4: 7 | XL4: 8 | XM4: 9 | XN4: 10 | XO4: 11 | XP4: 12 | XQ4: 13 | XR4: 14 | XS4: 15 | XT4: 16 | XU4: 17 | XV4: 18 | XW4: 19 | XX4: 20 | XY4: 21 | XZ4: 22 | YA4: 23 | YB4: 24 | YC4: 25 | YD4: 26 | YE4: 27 | YF4: 28 | YG4: 29 | YH4: 30 | YI4: 1 | YJ4: 2 | YK4: 3 | YL4: 4 | YM4: 5 | YN4: 6 | YO4: 7 | YP4: 8 | YQ4: 9 | YR4: 10 | YS4: 11 | YT4: 12 | YU4: 13 | YV4: 14 | YW4: 15 | YX4: 16 | YY4: 17 | YZ4: 18 | ZA4: 19 | ZB4: 20 | ZC4: 21 | ZD4: 22 | ZE4: 23 | ZF4: 24 | ZG4: 25 | ZH4: 26 | ZI4: 27 | ZJ4: 28 | ZK4: 29 | ZL4: 30 | ZM4: 31 | ZN4: 1 | ZO4: 2 | ZP4: 3 | ZQ4: 4 | ZR4: 5 | ZS4: 6 | ZT4: 7 | ZU4: 8 | ZV4: 9 | ZW4: 10 | ZX4: 11 | ZY4: 12 | ZZ4: 13 | AAA4: 14 | AAB4: 15 | AAC4: 16 | AAD4: 17 | AAE4: 18 | AAF4: 19 | AAG4: 20 | AAH4: 21 | AAI4: 22 | AAJ4: 23 | AAK4: 24 | AAL4: 25 | AAM4: 26 | AAN4: 27 | AAO4: 28 | AAP4: 29 | AAQ4: 30 | AAR4: 1 | AAS4: 2 | AAT4: 3 | AAU4: 4 | AAV4: 5 | AAW4: 6 | AAX4: 7 | AAY4: 8 | AAZ4: 9 | ABA4: 10 | ABB4: 11 | ABC4: 12 | ABD4: 13 | ABE4: 14 | ABF4: 15 | ABG4: 16 | ABH4: 17 | ABI4: 18 | ABJ4: 19 | ABK4: 20 | ABL4: 21 | ABM4: 22 | ABN4: 23 | ABO4: 24 | ABP4: 25 | ABQ4: 26 | ABR4: 27 | ABS4: 28 | ABT4: 29 | ABU4: 30 | ABV4: 31 | ABW4: 1 | ABX4: 2 | ABY4: 3 | ABZ4: 4 | ACA4: 5 | ACB4: 6 | ACC4: 7 | ACD4: 8 | ACE4: 9 | ACF4: 10 | ACG4: 11 | ACH4: 12 | ACI4: 13 | ACJ4: 14 | ACK4: 15 | ACL4: 16 | ACM4: 17 | ACN4: 18 | ACO4: 19 | ACP4: 20 | ACQ4: 21 | ACR4: 22 | ACS4: 23 | ACT4: 24 | ACU4: 25 | ACV4: 26 | ACW4: 27 | ACX4: 28 | ACY4: 29 | ACZ4: 30 | ADA4: 31 | ADB4: 1 | ADC4: 2 | ADD4: 3 | ADE4: 4 | ADF4: 5 | ADG4: 6 | ADH4: 7 | ADI4: 8 | ADJ4: 9 | ADK4: 10 | ADL4: 11 | ADM4: 12 | ADN4: 13 | ADO4: 14 | ADP4: 15 | ADQ4: 16 | ADR4: 17 | ADS4: 18 | ADT4: 19 | ADU4: 20 | ADV4: 21 | ADW4: 22 | ADX4: 23 | ADY4: 24 | ADZ4: 25 | AEA4: 26 | AEB4: 27 | AEC4: 28 | AED4: 1 | AEE4: 2 | AEF4: 3 | AEG4: 4 | AEH4: 5 | AEI4: 6 | AEJ4: 7 | AEK4: 8 | AEL4: 9 | AEM4: 10 | AEN4: 11 | AEO4: 12 | AEP4: 13 | AEQ4: 14 | AER4: 15 | AES4: 16 | AET4: 17 | AEU4: 18 | AEV4: 19 | AEW4: 20 | AEX4: 21 | AEY4: 22 | AEZ4: 23 | AFA4: 24 | AFB4: 25 | AFC4: 26 | AFD4: 27 | AFE4: 28 | AFF4: 29 | AFG4: 30 | AFH4: 31 | AFI4: 1 | AFJ4: 2 | AFK4: 3 | AFL4: 4 | AFM4: 5 | AFN4: 6 | AFO4: 7 | AFP4: 8 | AFQ4: 9 | AFR4: 10 | AFS4: 11 | AFT4: 12 | AFU4: 13 | AFV4: 14 | AFW4: 15 | AFX4: 16 | AFY4: 17 | AFZ4: 18 | AGA4: 19 | AGB4: 20 | AGC4: 21 | AGD4: 22 | AGE4: 23 | AGF4: 24 | AGG4: 25 | AGH4: 26 | AGI4: 27 | AGJ4: 28 | AGK4: 29 | AGL4: 30 | AGM4: 1 | AGN4: 2 | AGO4: 3 | AGP4: 4 | AGQ4: 5 | AGR4: 6 | AGS4: 7 | AGT4: 8 | AGU4: 9 | AGV4: 10 | AGW4: 11 | AGX4: 12 | AGY4: 13 | AGZ4: 14 | AHA4: 15 | AHB4: 16 | AHC4: 17 | AHD4: 18 | AHE4: 19 | AHF4: 20 | AHG4: 21 | AHH4: 22 | AHI4: 23 | AHJ4: 24 | AHK4: 25 | AHL4: 26 | AHM4: 27 | AHN4: 28 | AHO4: 29 | AHP4: 30 | AHQ4: 31 | AHR4: 1 | AHS4: 2 | AHT4: 3 | AHU4: 4 | AHV4: 5 | AHW4: 6 | AHX4: 7 | AHY4: 8 | AHZ4: 9 | AIA4: 10 | AIB4: 11 | AIC4: 12 | AID4: 13 | AIE4: 14 | AIF4: 15 | AIG4: 16 | AIH4: 17 | AII4: 18 | AIJ4: 19 | AIK4: 20 | AIL4: 21 | AIM4: 22 | AIN4: 23 | AIO4: 24 | AIP4: 25 | AIQ4: 26 | AIR4: 27 | AIS4: 28 | AIT4: 29 | AIU4: 30 | AIV4: 1 | AIW4: 2 | AIX4: 3 | AIY4: 4 | AIZ4: 5 | AJA4: 6 | AJB4: 7 | AJC4: 8 | AJD4: 9 | AJE4: 10 | AJF4: 11 | AJG4: 12 | AJH4: 13 | AJI4: 14 | AJJ4: 15 | AJK4: 16 | AJL4: 17 | AJM4: 18 | AJN4: 19 | AJO4: 20 | AJP4: 21 | AJQ4: 22 | AJR4: 23 | AJS4: 24 | AJT4: 25 | AJU4: 26 | AJV4: 27 | AJW4: 28 | AJX4: 29 | AJY4: 30 | AJZ4: 31 | AKA4: 1 | AKB4: 2 | AKC4: 3 | AKD4: 4 | AKE4: 5 | AKF4: 6 | AKG4: 7 | AKH4: 8 | AKI4: 9 | AKJ4: 10 | AKK4: 11 | AKL4: 12 | AKM4: 13 | AKN4: 14 | AKO4: 15 | AKP4: 16 | AKQ4: 17 | AKR4: 18 | AKS4: 19 | AKT4: 20 | AKU4: 21 | AKV4: 22 | AKW4: 23 | AKX4: 24 | AKY4: 25 | AKZ4: 26 | ALA4: 27 | ALB4: 28 | ALC4: 29 | ALD4: 30 | ALE4: 31 | ALF4: 1 | ALG4: 2 | ALH4: 3 | ALI4: 4 | ALJ4: 5 | ALK4: 6 | ALL4: 7 | ALM4: 8 | ALN4: 9 | ALO4: 10 | ALP4: 11 | ALQ4: 12 | ALR4: 13 | ALS4: 14 | ALT4: 15 | ALU4: 16 | ALV4: 17 | ALW4: 18 | ALX4: 19 | ALY4: 20 | ALZ4: 21 | AMA4: 22 | AMB4: 23 | AMC4: 24 | AMD4: 25 | AME4: 26 | AMF4: 27 | AMG4: 28 | AMH4: 29 | AMI4: 30 | AMJ4: 1 | AMK4: 2 | AML4: 3 | AMM4: 4 | AMN4: 5 | AMO4: 6 | AMP4: 7 | AMQ4: 8 | AMR4: 9 | AMS4: 10 | AMT4: 11 | AMU4: 12 | AMV4: 13 | AMW4: 14 | AMX4: 15 | AMY4: 16 | AMZ4: 17 | ANA4: 18 | ANB4: 19 | ANC4: 20 | AND4: 21 | ANE4: 22 | ANF4: 23 | ANG4: 24 | ANH4: 25 | ANI4: 26 | ANJ4: 27 | ANK4: 28 | ANL4: 29 | ANM4: 30 | ANN4: 31 | ANO4: 1 | ANP4: 2 | ANQ4: 3 | ANR4: 4 | ANS4: 5 | ANT4: 6 | ANU4: 7 | ANV4: 8 | ANW4: 9 | ANX4: 10 | ANY4: 11 | ANZ4: 12 | AOA4: 13 | AOB4: 14 | AOC4: 15 | AOD4: 16 | AOE4: 17 | AOF4: 18 | AOG4: 19 | AOH4: 20 | AOI4: 21 | AOJ4: 22 | AOK4: 23 | AOL4: 24 | AOM4: 25 | AON4: 26 | AOO4: 27 | AOP4: 28 | AOQ4: 29 | AOR4: 30 | AOS4: 1 | AOT4: 2 | AOU4: 3 | AOV4: 4 | AOW4: 5 | AOX4: 6 | AOY4: 7 | AOZ4: 8 | APA4: 9 | APB4: 10 | APC4: 11 | APD4: 12 | APE4: 13 | APF4: 14 | APG4: 15 | APH4: 16 | API4: 17 | APJ4: 18 | APK4: 19 | APL4: 20 | APM4: 21 | APN4: 22 | APO4: 23 | APP4: 24 | APQ4: 25 | APR4: 26 | APS4: 27 | APT4: 28 | APU4: 29 | APV4: 30 | APW4: 31
NE47: 原紙
CG176: ・

Sheet 製作班未定
J1: 忘 | BO1: 伊 | DG1: 石 | KL1: 石 | KN1: 休 | LN1: 伊 | OG1: 水 | OM1: 新規 液化酸素～ | PF1: ～工事 | QU1: 石
I2: 米 | J2: 年 | T2: 2 | U2: 0 | V2: 2 | W2: 4 | Y2: 部 | AM2: 米 | AX2: ク | BA2: 石 | BG2: 部 | BN2: 田 | BS2: ク | BZ2: 田 | CC2: 部 | CF2: 米 | CM2: 田 | CN2: 米 | CT2: 田 | DB2: ク | DG2: 現 | DK2: 部 | DW2: 田 | EU2: 部 | FI2: B | FV2: 部 | GA2: 田 | GQ2: 米 | GX2: 石 | IZ2: ク | JU2: ク | KB2: 健 | KC2: 康 | KE2: 米 | KV2: 石 | KW2: ク | LQ2: 石 | LS2: 田 | MF2: ク | NB2: 米 | NV2: 2 | NW2: 0 | NX2: 2 | NY2: 5 | OG2: 素 | PM2: 米 | PS2: ク | QA2: 田 | QG2: 田 | QW2: 米 | RE2: 米 | RK2: 石 | RP2: 田 | ABW2: 2 | ABX2: 0 | ABY2: 2 | ABZ2: 6 | APX2: 2 | APY2: 0 | APZ2: 2 | AQA2: 7
